Workbook

Sheet SUM ppob
B1: CASH FLOW
B2: BUMDES "BAROKAH" BALONGBESUK DIWEK JOMBANG
B3: TAHUN ANGGARAN 2021
B4: UNIT USAHA PPOB/AGEN POS
B7: CODE | C7: URAIAN | E7: 2021 | K7: TOTAL
E8: Januari | F8: Pebruari | G8: Maret | H8: April | I8: Mei | J8: Juni
B10: 1000 | C10: DANA AWAL | E10: =SUMIF('CTH lapak'!$B$8:$B$20,B10,'CTH lapak'!$E$8:$E$20) -> 0 | F10: =SUMIF('CTH lapak'!#REF!,B10,'CTH lapak'!#REF!) -> #REF! | G10: =SUMIF('CTH lapak'!#REF!,B10,'CTH lapak'!#REF!) -> #REF! | H10: =SUMIF('CTH lapak'!#REF!,B10,'CTH lapak'!#REF!) -> #REF! | I10: =SUMIF('CTH lapak'!#REF!,B10,'CTH lapak'!#REF!) -> #REF! | J10: =SUMIF('CTH lapak'!#REF!,B10,'CTH lapak'!#REF!) -> #REF! | K10: =SUM(D10:J10) -> #REF!
B12: 2000 | C12: PENDAPATAN | D12: =SUM(D13:D13) -> 0 | E12: =SUM(E13:E13) -> 16500000 | F12: =SUM(F13:F13) -> #REF! | G12: =SUM(G13:G13) -> #REF! | H12: =SUM(H13:H13) -> #REF! | I12: =SUM(I13:I13) -> #REF! | J12: =SUM(J13:J13) -> #REF! | K12: =SUM(K13:K13) -> #REF!
B13: 2001 | C13: Pendapatan Transaksi | E13: =SUMIF('CTH lapak'!$B$8:$B$20,B13,'CTH lapak'!$E$8:$E$20) -> 16500000 | F13: =SUMIF('CTH lapak'!#REF!,B13,'CTH lapak'!#REF!) -> #REF! | G13: =SUMIF('CTH lapak'!#REF!,B13,'CTH lapak'!#REF!) -> #REF! | H13: =SUMIF('CTH lapak'!#REF!,B13,'CTH lapak'!#REF!) -> #REF! | I13: =SUMIF('CTH lapak'!#REF!,B13,'CTH lapak'!#REF!) -> #REF! | J13: =SUMIF('CTH lapak'!#REF!,B13,'CTH lapak'!#REF!) -> #REF! | K13: =SUM(D13:J13) -> #REF!
B15: 3000 | C15: DEPOSITO | D15: =SUM(D16:D17) -> 0 | E15: =SUM(E16:E17) -> 0 | F15: =SUM(F16:F17) -> 0 | G15: =SUM(G16:G17) -> 0 | H15: =SUM(H16:H17) -> 0 | I15: =SUM(I16:I17) -> 0 | J15: =SUM(J16:J17) -> 0 | K15: =SUM(K16:K17) -> 0
B16: 3001 | C16: Deposito | E16: =SUMIF('cth gEDUNG'!$B$8:$B$26,B16,'cth gEDUNG'!$M$8:$M$26) -> 0 | F16: =SUMIF('cth gEDUNG'!$B$33:$B$49,B16,'cth gEDUNG'!$M$33:$M$49) -> 0 | G16: =SUMIF('cth gEDUNG'!$B$57:$B$67,B16,'cth gEDUNG'!$M$57:$M$67) -> 0 | H16: =SUMIF('cth gEDUNG'!$B$75:$B$88,B16,'cth gEDUNG'!$M$75:$M$88) -> 0 | I16: =SUMIF('cth gEDUNG'!$B$96:$B$110,B16,'cth gEDUNG'!$M$96:$M$110) -> 0 | J16: =SUMIF('cth gEDUNG'!$B$118:$B$135,B16,'cth gEDUNG'!$M$118:$M$135) -> 0 | K16: =SUM(D16:J16) -> 0
E17: =SUMIF('cth gEDUNG'!$B$8:$B$26,B17,'cth gEDUNG'!$E$8:$E$26) -> 0 | F17: =SUMIF('cth gEDUNG'!$B$33:$B$49,B17,'cth gEDUNG'!$E$33:$E$49) -> 0 | G17: =SUMIF('cth gEDUNG'!$B$57:$B$67,B17,'cth gEDUNG'!$E$57:$E$67) -> 0 | H17: =SUMIF('cth gEDUNG'!$B$75:$B$88,B17,'cth gEDUNG'!$E$75:$E$88) -> 0 | I17: =SUMIF('cth gEDUNG'!$B$96:$B$110,B17,'cth gEDUNG'!$E$96:$E$110) -> 0 | J17: =SUMIF('cth gEDUNG'!$B$118:$B$135,B17,'cth gEDUNG'!$E$118:$E$135) -> 0 | K17: =SUM(D17:J17) -> 0
C19: TOTAL MASUK | D19: =D10+D12+D15 -> 0 | E19: =E10+E12+E15 -> 16500000 | F19: =F10+F12+F15 -> #REF! | G19: =G10+G12+G15 -> #REF! | H19: =H10+H12+H15 -> #REF! | I19: =I10+I12+I15 -> #REF! | J19: =J10+J12+J15 -> #REF! | K19: =K10+K12+K15 -> #REF!
K20: =SUM(E20:G20) -> 0
B21: 5000 | C21: BELANJA | E21: =E22 -> 3734850 | F21: =F22 -> #REF! | G21: =G22 -> #REF! | H21: =H22 -> #REF! | I21: =I22 -> #REF! | J21: =J22 -> #REF! | K21: =K22 -> #REF!
B22: 5100 | C22: Operasional | E22: =SUM(E23:E29) -> 3734850 | F22: =SUM(F23:F29) -> #REF! | G22: =SUM(G23:G29) -> #REF! | H22: =SUM(H23:H29) -> #REF! | I22: =SUM(I23:I29) -> #REF! | J22: =SUM(J23:J29) -> #REF! | K22: =SUM(K23:K29) -> #REF!
B23: 5101 | C23: Gaji/Honor Pegawai | E23: =SUMIF('CTH lapak'!$B$8:$B$20,B23,'CTH lapak'!$F$8:$F$20) -> 0 | F23: =SUMIF('CTH lapak'!#REF!,B23,'CTH lapak'!#REF!) -> #REF! | G23: =SUMIF('CTH lapak'!#REF!,B23,'CTH lapak'!#REF!) -> #REF! | H23: =SUMIF('CTH lapak'!#REF!,B23,'CTH lapak'!#REF!) -> #REF! | I23: =SUMIF('CTH lapak'!#REF!,B23,'CTH lapak'!#REF!) -> #REF! | J23: =SUMIF('CTH lapak'!#REF!,B23,'CTH lapak'!#REF!) -> #REF! | K23: =SUM(D23:J23) -> #REF!
B24: 5102 | C24: Transportasi | E24: =SUMIF('CTH lapak'!$B$8:$B$20,B24,'CTH lapak'!$F$8:$F$20) -> 1300000 | F24: =SUMIF('CTH lapak'!#REF!,B24,'CTH lapak'!#REF!) -> #REF! | G24: =SUMIF('CTH lapak'!#REF!,B24,'CTH lapak'!#REF!) -> #REF! | H24: =SUMIF('CTH lapak'!#REF!,B24,'CTH lapak'!#REF!) -> #REF! | I24: =SUMIF('CTH lapak'!#REF!,B24,'CTH lapak'!#REF!) -> #REF! | J24: =SUMIF('CTH lapak'!#REF!,B24,'CTH lapak'!#REF!) -> #REF! | K24: =SUM(D24:J24) -> #REF!
B25: 5103 | C25: Peralatan Kebersihan | E25: =SUMIF('CTH lapak'!$B$8:$B$20,B25,'CTH lapak'!$F$8:$F$20) -> 0 | F25: =SUMIF('CTH lapak'!#REF!,B25,'CTH lapak'!#REF!) -> #REF! | G25: =SUMIF('CTH lapak'!#REF!,B25,'CTH lapak'!#REF!) -> #REF! | H25: =SUMIF('CTH lapak'!#REF!,B25,'CTH lapak'!#REF!) -> #REF! | I25: =SUMIF('CTH lapak'!#REF!,B25,'CTH lapak'!#REF!) -> #REF! | J25: =SUMIF('CTH lapak'!#REF!,B25,'CTH lapak'!#REF!) -> #REF! | K25: =SUM(D25:J25) -> #REF!
B26: 5104 | C26: Listrik | E26: =SUMIF('CTH lapak'!$B$8:$B$20,B26,'CTH lapak'!$F$8:$F$20) -> 0 | F26: =SUMIF('CTH lapak'!#REF!,B26,'CTH lapak'!#REF!) -> #REF! | G26: =SUMIF('CTH lapak'!#REF!,B26,'CTH lapak'!#REF!) -> #REF! | H26: =SUMIF('CTH lapak'!#REF!,B26,'CTH lapak'!#REF!) -> #REF! | I26: =SUMIF('CTH lapak'!#REF!,B26,'CTH lapak'!#REF!) -> #REF! | J26: =SUMIF('CTH lapak'!#REF!,B26,'CTH lapak'!#REF!) -> #REF! | K26: =SUM(D26:J26) -> #REF!
B27: 5105 | C27: Peralatan Listrik | E27: =SUMIF('CTH lapak'!$B$8:$B$20,B27,'CTH lapak'!$F$8:$F$20) -> 0 | F27: =SUMIF('CTH lapak'!#REF!,B27,'CTH lapak'!#REF!) -> #REF! | G27: =SUMIF('CTH lapak'!#REF!,B27,'CTH lapak'!#REF!) -> #REF! | H27: =SUMIF('CTH lapak'!#REF!,B27,'CTH lapak'!#REF!) -> #REF! | I27: =SUMIF('CTH lapak'!#REF!,B27,'CTH lapak'!#REF!) -> #REF! | J27: =SUMIF('CTH lapak'!#REF!,B27,'CTH lapak'!#REF!) -> #REF! | K27: =SUM(D27:J27) -> #REF!
B28: 5106 | C28: Perlengkapan | E28: =SUMIF('CTH lapak'!$B$8:$B$20,B28,'CTH lapak'!$F$8:$F$20) -> 0 | F28: =SUMIF('CTH lapak'!#REF!,B28,'CTH lapak'!#REF!) -> #REF! | G28: =SUMIF('CTH lapak'!#REF!,B28,'CTH lapak'!#REF!) -> #REF! | H28: =SUMIF('CTH lapak'!#REF!,B28,'CTH lapak'!#REF!) -> #REF! | I28: =SUMIF('CTH lapak'!#REF!,B28,'CTH lapak'!#REF!) -> #REF! | J28: =SUMIF('CTH lapak'!#REF!,B28,'CTH lapak'!#REF!) -> #REF! | K28: =SUM(D28:J28) -> #REF!
B29: 5109 | C29: Perawaan Lain-Lain | E29: =SUMIF('CTH lapak'!$B$8:$B$20,B29,'CTH lapak'!$F$8:$F$20) -> 2434850 | F29: =SUMIF('CTH lapak'!#REF!,B29,'CTH lapak'!#REF!) -> #REF! | G29: =SUMIF('CTH lapak'!#REF!,B29,'CTH lapak'!#REF!) -> #REF! | H29: =SUMIF('CTH lapak'!#REF!,B29,'CTH lapak'!#REF!) -> #REF! | I29: =SUMIF('CTH lapak'!#REF!,B29,'CTH lapak'!#REF!) -> #REF! | J29: =SUMIF('CTH lapak'!#REF!,B29,'CTH lapak'!#REF!) -> #REF! | K29: =SUM(D29:J29) -> #REF!
K30: =SUM(D30:J30) -> 0
B31: 5200 | C31: PERLENGKAPAN | E31: =E32 -> 1200000 | F31: =F32 -> #REF! | G31: =G32 -> #REF! | H31: =H32 -> #REF! | I31: =I32 -> #REF! | J31: =J32 -> #REF! | K31: =SUM(D31:J31) -> #REF!
B32: 5201 | C32: Printer | E32: =SUMIF('CTH lapak'!$B$8:$B$20,B32,'CTH lapak'!$F$8:$F$20) -> 1200000 | F32: =SUMIF('CTH lapak'!#REF!,B32,'CTH lapak'!#REF!) -> #REF! | G32: =SUMIF('CTH lapak'!#REF!,B32,'CTH lapak'!#REF!) -> #REF! | H32: =SUMIF('CTH lapak'!#REF!,B32,'CTH lapak'!#REF!) -> #REF! | I32: =SUMIF('CTH lapak'!#REF!,B32,'CTH lapak'!#REF!) -> #REF! | J32: =SUMIF('CTH lapak'!#REF!,B32,'CTH lapak'!#REF!) -> #REF! | K32: =SUM(D32:J32) -> #REF!
B34: 3000 | C34: DEPOSIT | E34: =SUM(E35:E35) -> 0 | F34: =SUM(F35:F35) -> 0 | G34: =SUM(G35:G35) -> 0 | H34: =SUM(H35:H35) -> 0 | I34: =SUM(I35:I35) -> 0 | J34: =SUM(J35:J35) -> 0 | K34: =SUM(K35:K35) -> 0
B35: 3001 | C35: DEPOSIT | K35: =SUM(D35:J35) -> 0
E36: =SUMIF('cth gEDUNG'!$B$8:$B$26,B36,'cth gEDUNG'!$F$8:$F$26) -> 0 | F36: =SUMIF('cth gEDUNG'!$B$33:$B$49,B36,'cth gEDUNG'!$F$33:$F$49) -> 0 | G36: =SUMIF('cth gEDUNG'!$B$57:$B$67,B36,'cth gEDUNG'!$F$57:$F$67) -> 0 | H36: =SUMIF('cth gEDUNG'!$B$75:$B$88,B36,'cth gEDUNG'!$F$75:$F$88) -> 0 | I36: =SUMIF('cth gEDUNG'!$B$96:$B$110,B36,'cth gEDUNG'!$F$96:$F$110) -> 0 | J36: =SUMIF('cth gEDUNG'!$B$118:$B$135,B36,'cth gEDUNG'!$F$118:$F$135) -> 0 | K36: =SUM(E36:J36) -> 0
C37: JUMLAH | E37: =E34+E21+E31 -> 4934850 | F37: =F34+F21+F31 -> #REF! | G37: =G34+G21+G31 -> #REF! | H37: =H34+H21+H31 -> #REF! | I37: =I34+I21+I31 -> #REF! | J37: =J34+J21+J31 -> #REF! | K37: =K34+K21 -> #REF!
C38: SURPLUS / DEVISIT | E38: =E19-E37 -> 11565150 | F38: =F19-F37 -> #REF! | G38: =G19-G37 -> #REF! | H38: =H19-H37 -> #REF! | I38: =I19-I37 -> #REF! | J38: =J19-J37 -> #REF! | K38: =K19-K37 -> #REF!
B41: CASH FLOW
B42: BUMDES "BAROKAH" BALONGBESUK DIWEK JOMBANG
B43: TAHUN ANGGARAN 2021
B44: UNIT USAHA GEDUNG SERBA GUNA
B47: CODE | C47: URAIAN | D47: S/D JUNI | E47: 2021 | K47: TOTAL
E48: Juli | F48: Agustus | G48: September | H48: Oktober | I48: Nopember | J48: Desember
B50: 1000 | C50: DANA AWAL | D50: =K10 -> #REF! | F50: =SUMIF('cth sp'!$B$89:$B$107,B50,'cth sp'!$E$89:$E$107) -> 0 | K50: =SUM(E50:G50) -> 0
B52: 2000 | C52: PENDAPATAN | D52: =SUM(D53:D53) -> #REF! | E52: =SUM(E53:E53) -> #REF! | F52: =SUM(F53:F53) -> #REF! | G52: =SUM(G53:G53) -> #REF! | H52: =SUM(H53:H53) -> #REF! | I52: =SUM(I53:I53) -> #REF! | J52: =SUM(J53:J53) -> #REF! | K52: =SUM(K53:K53) -> #REF!
B53: 2001 | C53: Pendapatan Transaksi | D53: =K13 -> #REF! | E53: =SUMIF('CTH lapak'!#REF!,B53,'CTH lapak'!#REF!) -> #REF! | F53: =SUMIF('CTH lapak'!#REF!,B53,'CTH lapak'!#REF!) -> #REF! | G53: =SUMIF('CTH lapak'!#REF!,B53,'CTH lapak'!#REF!) -> #REF! | H53: =SUMIF('CTH lapak'!#REF!,B53,'CTH lapak'!#REF!) -> #REF! | I53: =SUMIF('CTH lapak'!#REF!,B53,'CTH lapak'!#REF!) -> #REF! | J53: =SUMIF('CTH lapak'!#REF!,B53,'CTH lapak'!#REF!) -> #REF! | K53: =SUM(D53:J53) -> #REF!
...

Sheet hutang sewa
A1: DATA PEMILIK LAPAK
D3: =SUM(D5:D15) -> 18 | F3: PIUTANG KOMITMEN | G3: =SUM(G5:G15) -> 26550000 | J3: =E5/12 -> 166666.67
A4: NO | B4: NOMOR LAPAK | C4: NAMA | D4: lapak | E4: SATUAN | F4: NILAI KONTRAK | G4: MASUK 22 | H4: MASUK 23 | I4: SISA PIUTANG | J4: Nilai Pemakaian | K4: 2022 | L4: 2023 | M4: 2024 | N4: NILAI BUKU
A5: L01 | B5: 4-5-6 | C5: ONI | D5: 3 | E5: 2000000 | F5: =D5*E5 -> 6000000 | G5: 4800000 | H5: =SUMIF('CTH lapak'!$M$8:$M$25,A5,'CTH lapak'!$O$8:$O$25) -> 0 | I5: =F5-(G5+H5) -> 1200000 | K5: 0 | L5: =J5*$J$3 -> 0 | N5: =F5-K5-L5-M5 -> 6000000
A6: L02 | B6: 10-11 | C6: KABUL | D6: 2 | E6: 2000000 | F6: =D6*E6 -> 4000000 | G6: 4000000 | H6: =SUMIF('CTH lapak'!$M$8:$M$25,A6,'CTH lapak'!$O$8:$O$25) -> 0 | I6: =F6-(G6+H6) -> 0 | J6: 0 | K6: 0 | L6: =J6*$J$3 -> 0 | N6: =F6-K6-L6-M6 -> 4000000
A7: L03 | B7: 15-16 | C7: GANO | D7: 2 | E7: 2000000 | F7: =D7*E7 -> 4000000 | G7: 2000000 | H7: =SUMIF('CTH lapak'!$M$8:$M$25,A7,'CTH lapak'!$O$8:$O$25) -> 0 | I7: =F7-(G7+H7) -> 2000000 | K7: 0 | L7: =J7*$J$3 -> 0 | N7: =F7-K7-L7-M7 -> 4000000
A8: L04 | B8: 33 | C8: DESI | D8: 1 | E8: 2000000 | F8: =D8*E8 -> 2000000 | G8: 2000000 | H8: =SUMIF('CTH lapak'!$M$8:$M$25,A8,'CTH lapak'!$O$8:$O$25) -> 0 | I8: =F8-(G8+H8) -> 0 | K8: 0 | L8: =J8*$J$3 -> 0 | N8: =F8-K8-L8-M8 -> 2000000
A9: L05 | B9: 34 | C9: SARIMAN | D9: 1 | E9: 2000000 | F9: =D9*E9 -> 2000000 | G9: 1250000 | H9: =SUMIF('CTH lapak'!$M$8:$M$25,A9,'CTH lapak'!$O$8:$O$25) -> 0 | I9: =F9-(G9+H9) -> 750000 | K9: 0 | L9: =J9*$J$3 -> 0 | N9: =F9-K9-L9-M9 -> 2000000
A10: L06 | B10: 38-39 | C10: SUHARTIN | D10: 2 | E10: 2000000 | F10: =D10*E10 -> 4000000 | G10: 3000000 | H10: =SUMIF('CTH lapak'!$M$8:$M$25,A10,'CTH lapak'!$O$8:$O$25) -> 0 | I10: =F10-(G10+H10) -> 1000000 | K10: 0 | L10: =J10*$J$3 -> 0 | N10: =F10-K10-L10-M10 -> 4000000
A11: L07 | B11: 42 | C11: YULI | D11: 1 | E11: 2000000 | F11: =D11*E11 -> 2000000 | G11: 2000000 | H11: =SUMIF('CTH lapak'!$M$8:$M$25,A11,'CTH lapak'!$O$8:$O$25) -> 0 | I11: =F11-(G11+H11) -> 0 | K11: 0 | L11: =J11*$J$3 -> 0 | N11: =F11-K11-L11-M11 -> 2000000
A12: L08 | B12: 43-44 | C12: HARTOYO / SUSILO | D12: 2 | E12: 2000000 | F12: =D12*E12*2 -> 8000000 | G12: 3000000 | H12: =SUMIF('CTH lapak'!$M$8:$M$25,A12,'CTH lapak'!$O$8:$O$25) -> 0 | I12: =F12-(G12+H12) -> 5000000 | J12: 24 | K12: 4000000 | L12: =J12*$J$3 -> 4000000 | N12: =F12-K12-L12-M12 -> 0
A13: L09 | B13: 45 | C13: KASTIN | D13: 1 | E13: 2000000 | F13: =D13*E13 -> 2000000 | G13: 1500000 | H13: =SUMIF('CTH lapak'!$M$8:$M$25,A13,'CTH lapak'!$O$8:$O$25) -> 0 | I13: =F13-(G13+H13) -> 500000 | K13: 0 | L13: =J13*$J$3 -> 0 | N13: =F13-K13-L13-M13 -> 2000000
A14: L10 | B14: 46-47 | C14: KHOLIL | D14: 2 | E14: 2000000 | F14: =D14*E14 -> 4000000 | G14: 2000000 | H14: =SUMIF('CTH lapak'!$M$8:$M$25,A14,'CTH lapak'!$O$8:$O$25) -> 0 | I14: =F14-(G14+H14) -> 2000000 | J14: 12 | K14: 2000000 | L14: =J14*$J$3 -> 2000000 | N14: =F14-K14-L14-M14 -> 0
A15: L11 | B15: 12 | C15: SUPARMAN | D15: 1 | E15: 2000000 | F15: =D15*E15 -> 2000000 | G15: 1000000 | H15: =SUMIF('CTH lapak'!$M$8:$M$25,A15,'CTH lapak'!$O$8:$O$25) -> 0 | I15: =F15-(G15+H15) -> 1000000 | K15: 0 | L15: =J15*$J$3 -> 0 | N15: =F15-K15-L15-M15 -> 2000000
A16: L12 | B16: 1-2-3 | C16: AGUS SUSANTO | D16: 3 | F16: =D16*E16 -> 0 | H16: =SUMIF('CTH lapak'!$M$8:$M$25,A16,'CTH lapak'!$O$8:$O$25) -> 0 | I16: =F16-(G16+H16) -> 0 | K16: 0 | L16: =J16*$J$3 -> 0 | N16: =F16-K16-L16-M16 -> 0
A17: L13 | B17: 7 | C17: WASIS | D17: 1 | F17: =D17*E17 -> 0 | I17: =F17-(G17+H17) -> 0 | K17: 0 | L17: =J17*$J$3 -> 0 | N17: =F17-K17-L17-M17 -> 0
A18: L14 | B18: 8 | C18: SAMSUL ARIFIN | D18: 1 | F18: =D18*E18 -> 0 | I18: =F18-(G18+H18) -> 0 | K18: 0 | L18: =J18*$J$3 -> 0 | N18: =F18-K18-L18-M18 -> 0
A19: L15 | B19: 9 | C19: FEBRI | D19: 1 | F19: =D19*E19 -> 0 | I19: =F19-(G19+H19) -> 0 | K19: 0 | L19: =J19*$J$3 -> 0 | N19: =F19-K19-L19-M19 -> 0
A20: L16 | B20: 14 | C20: SAMIADI | D20: 1 | F20: =D20*E20 -> 0 | I20: =F20-(G20+H20) -> 0 | K20: 0 | L20: =J20*$J$3 -> 0 | N20: =F20-K20-L20-M20 -> 0
A21: L17 | B21: 19 | C21: DENOK/ARIFIN | D21: 1 | F21: =D21*E21 -> 0 | I21: =F21-(G21+H21) -> 0 | K21: 0 | L21: =J21*$J$3 -> 0 | N21: =F21-K21-L21-M21 -> 0
A22: L18 | B22: 26 | C22: - | D22: 1 | F22: =D22*E22 -> 0 | I22: =F22-(G22+H22) -> 0 | K22: 0 | L22: =J22*$J$3 -> 0 | N22: =F22-K22-L22-M22 -> 0
A23: L19 | B23: 29-30-31-32 | C23: BUMDES | D23: 4 | F23: =D23*E23 -> 0 | I23: =F23-(G23+H23) -> 0 | K23: 0 | L23: =J23*$J$3 -> 0 | N23: =F23-K23-L23-M23 -> 0
A24: L20 | B24: 35-36-37 | C24: YULIANTO | D24: 3 | F24: =D24*E24 -> 0 | I24: =F24-(G24+H24) -> 0 | K24: 0 | L24: =J24*$J$3 -> 0 | N24: =F24-K24-L24-M24 -> 0
A25: L21 | B25: 40-41 | C25: PITA/EDI/WADUK | D25: 2 | F25: =D25*E25 -> 0 | I25: =F25-(G25+H25) -> 0 | K25: 0 | L25: =J25*$J$3 -> 0 | N25: =F25-K25-L25-M25 -> 0
A26: L22 | B26: 45 | C26: - | D26: 1 | F26: =D26*E26 -> 0 | I26: =F26-(G26+H26) -> 0 | K26: 0 | L26: =J26*$J$3 -> 0 | N26: =F26-K26-L26-M26 -> 0
A27: L23 | B27: 13 | C27: SUWONO | D27: 1 | E27: 2000000 | F27: =D27*E27 -> 2000000 | H27: =SUMIF('CTH lapak'!$M$8:$M$25,A27,'CTH lapak'!$O$8:$O$25) -> 0 | I27: =F27-(G27+H27) -> 2000000 | K27: 2000000 | L27: =J27*$J$3 -> 0 | N27: =F27-K27-L27-M27 -> 0
A28: L24 | B28: 17-18 | C28: SIAMI | D28: 2 | E28: 2000000 | F28: =D28*E28 -> 4000000 | H28: =SUMIF('CTH lapak'!$M$8:$M$25,A28,'CTH lapak'!$O$8:$O$25) -> 0 | I28: =F28-(G28+H28) -> 4000000 | K28: 4000000 | L28: =J28*$J$3 -> 0 | N28: =F28-K28-L28-M28 -> 0
A29: L25 | B29: 22 | C29: LUSTIYO YUNINGSIH | D29: 1 | E29: 2000000 | F29: =D29*E29 -> 2000000 | H29: =SUMIF('CTH lapak'!$M$8:$M$25,A29,'CTH lapak'!$O$8:$O$25) -> 0 | I29: =F29-(G29+H29) -> 2000000 | K29: 2000000 | L29: =J29*$J$3 -> 0 | N29: =F29-K29-L29-M29 -> 0
A30: L26 | B30: 23-24 | C30: SUNAWI | D30: 2 | E30: 2000000 | F30: =D30*E30 -> 4000000 | H30: =SUMIF('CTH lapak'!$M$8:$M$25,A30,'CTH lapak'!$O$8:$O$25) -> 0 | I30: =F30-(G30+H30) -> 4000000 | K30: 4000000 | L30: =J30*$J$3 -> 0 | N30: =F30-K30-L30-M30 -> 0
A31: L27 | B31: 27-28 | C31: MUNJIROH | D31: 2 | E31: 2000000 | F31: =D31*E31 -> 4000000 | H31: =SUMIF('CTH lapak'!$M$8:$M$25,A31,'CTH lapak'!$O$8:$O$25) -> 0 | I31: =F31-(G31+H31) -> 4000000 | K31: 4000000 | L31: =J31*$J$3 -> 0 | N31: =F31-K31-L31-M31 -> 0
A32: L28 | B32: 21 | C32: SUMARMI | D32: 1 | E32: 2000000 | F32: =D32*E32 -> 2000000 | H32: =SUMIF('CTH lapak'!$M$8:$M$25,A32,'CTH lapak'!$O$8:$O$25) -> 0 | I32: =F32-(G32+H32) -> 2000000 | K32: 2000000 | L32: =J32*$J$3 -> 0 | N32: =F32-K32-L32-M32 -> 0
A33: L29 | B33: 20 | C33: RISTAKUL JANAH | D33: 1 | E33: 2000000 | F33: =D33*E33 -> 2000000 | H33: =SUMIF('CTH lapak'!$M$8:$M$25,A33,'CTH lapak'!$O$8:$O$25) -> 0 | I33: =F33-(G33+H33) -> 2000000 | K33: 2000000 | L33: =J33*$J$3 -> 0 | N33: =F33-K33-L33-M33 -> 0
A34: L30 | B34: 25 | C34: SUGIATI | D34: 1 | E34: 2000000 | F34: =D34*E34 -> 2000000 | H34: =SUMIF('CTH lapak'!$M$8:$M$25,A34,'CTH lapak'!$O$8:$O$25) -> 0 | I34: =F34-(G34+H34) -> 2000000 | K34: 2000000 | L34: =J34*$J$3 -> 0 | N34: =F34-K34-L34-M34 -> 0
D35: =SUM(D5:D34) -> 48 | F35: =SUM(F5:F34) -> 62000000 | G35: =SUM(G5:G34) -> 26550000 | H35: =SUM(H5:H34) -> 0 | I35: =SUM(I5:I34) -> 35450000 | J35: =SUM(J5:J34) -> 36 | K35: =SUM(K5:K34) -> 28000000 | L35: =SUM(L5:L34) -> 6000000 | M35: =SUM(M5:M34) -> 0 | N35: =SUM(N5:N34) -> 28000000
D36: =SUM(D27:D34) -> 11 | E36: =E35/D35 -> 0 | F36: =F35/D35 -> 1291666.7

Sheet Sheet1
C2: 2021
C3: 2023
A4: TAGUN ANGGARAN | B4: : | C4: TAHUN ANGGARAN 2025
A5: TUTUP BUKU | B5: : | C5: 31 - DESEMBER 2025
C6: BADAN USAHA MILIK DESA
A7: BADAN USAHA MILIK DESA | B7: : | C7: " BAROKAH "
A8: DESA | B8: : | C8: Desa Balongbesuk Kecamatan Diwek Kabupaten Jombang
A10: Ketua | C10: NUR SALIM
A11: Sekretaris
A12: Bendahara | C12: MAMIK KURNIAWATI

Sheet BANK
A1: =Sheet1!A7 -> BADAN USAHA MILIK DESA
A2: =Sheet1!C7 -> " BAROKAH "
A3: =Sheet1!C8 -> Desa Balongbesuk Kecamatan Diwek Kabupaten Jombang
A4: =Sheet1!C4 -> TAHUN ANGGARAN 2025
A6: BUKU BANTU TRANSAKSI BANK
A8: No | B8: Bulan | C8: Bunga | D8: Admin | E8: Pajak atas Bunga
A11: 1 | B11: Januari 2025 | C11: 19728.29 | D11: 5000 | E11: 3945.65
A12: 2 | B12: Pebruari 2025 | C12: 17829.42 | D12: 5000 | E12: 3565.884
A13: 3 | B13: Maret 2025 | C13: 19749.57 | D13: 5000 | E13: 3949.914
A14: 4 | B14: April 2025 | C14: 19123.58 | D14: 5000 | E14: 3824.71
A15: 5 | B15: Mei 2025 | C15: 19771 | D15: 5000 | E15: 3954
A16: 6 | B16: Juni 2025 | C16: 22974 | D16: 5000 | E16: 4594
A17: 7 | B17: Juli 2025 | C17: 23757 | D17: 5000 | E17: 4751
A18: 8 | B18: Agustus 2025 | C18: 23775 | D18: 5000 | E18: 4755
A19: 9 | B19: September 2025 | C19: 23025 | D19: 5000 | E19: 4605
A20: 10 | B20: Oktober 2025 | C20: 23809 | D20: 5000 | E20: 4761.8
A21: 11 | B21: Nopember 2025 | C21: 23059 | D21: 5000 | E21: 4611.8
A22: 12 | B22: Desember 2025 | C22: 142575 | E22: 28515
C23: =SUM(C11:C22) -> 379175.86 | D23: =SUM(D11:D22) -> 55000 | E23: =SUM(E11:E22) -> 75833.758
D25: ='LAPORAN LABA'!D63 -> Balongbesuk, 15 Januari 2025
B26: ='LAPORAN LABA'!C64 -> Dilaporkan Oleh; | D26: ='LAPORAN LABA'!D64 -> Dibuat Oleh;
B30: =NERACA!I39 -> DODIK SUSANTO, S.Fil.I | D30: =Sheet1!C12 -> MAMIK KURNIAWATI
B31: ='LAPORAN LABA'!C68 -> Direktur BUMDesa "BAROKAH" | D31: =NERACA!J40 -> Bendahara BUMDesa "BAROKAH"

Sheet piutang
A1: DAFTAR PIUTANG
A2: BUMDES 'BAROKAH'
A3: Desa Balongbesuk Kec. Diwek Jombang
A4: s/d Desember 2025 | O4: 15000000 | P4: 20000000 | Q4: 15000000 | R4: =50000000-O4+P4-Q4 -> 40000000
A6: NO | B6: CODE | C6: NAMA | D6: PIUTANG THN LALU 2024 | E6: Tahun 2025 | K6: MASUK | L6: KELUAR | M6: SISA PIUTANG
E7: Mei | G7: Nopember | I7: Desember | O7: angsuran | P7: bunga | Q7: admin | R7: tabungan | S7: jumlah
E8: MASUK | F8: KELUAR | G8: MASUK | H8: KELUAR | I8: MASUK | J8: KELUAR
B9: A-000 | C9: GAPOKTAN | D9: 33000000 | E9: =SUMIF('cth sp'!$M$9:$M$107,B9,'cth sp'!$N$9:$N$107) -> 0 | F9: =SUMIF('cth sp'!$M$9:$M$107,B9,'cth sp'!$O$9:$O$107) -> 5000000 | G9: =SUMIF('cth sp'!$M$114:$M$158,B9,'cth sp'!$N$114:$N$158) -> 0 | H9: =SUMIF('cth sp'!$M$114:$M$158,B9,'cth sp'!$O$114:$O$158) -> 0 | I9: =SUMIF('cth sp'!$M$165:$M$389,B9,'cth sp'!$N$165:$N$389) -> 0 | J9: =SUMIF('cth sp'!$M$159:$M$389,B9,'cth sp'!$O$159:$O$389) -> 0 | K9: =E9+G9+I9 -> 0 | L9: =F9+H9+J9 -> 5000000 | M9: =D9+K9-L9 -> 28000000 | S9: =SUM(O9:R9) -> 0
A10: 1 | B10: A-001 | C10: Sri Jayanti | D10: 1000000 | E10: =SUMIF('cth sp'!$M$9:$M$107,B10,'cth sp'!$N$9:$N$107) -> 1000000 | F10: =SUMIF('cth sp'!$M$9:$M$107,B10,'cth sp'!$O$9:$O$107) -> 1000000 | G10: =SUMIF('cth sp'!$M$114:$M$158,B10,'cth sp'!$N$114:$N$158) -> 0 | H10: =SUMIF('cth sp'!$M$114:$M$158,B10,'cth sp'!$O$114:$O$158) -> 0 | I10: =SUMIF('cth sp'!$M$159:$M$389,B10,'cth sp'!$N$159:$N$389) -> 0 | J10: =SUMIF('cth sp'!$M$159:$M$389,B10,'cth sp'!$O$159:$O$389) -> 0 | K10: =E10+G10+I10 -> 1000000 | L10: =F10+H10+J10 -> 1000000 | M10: =D10+K10-L10 -> 1000000 | S10: =SUM(O10:R10) -> 0 | T10: 280000
A11: 2 | B11: A-002 | C11: Adi Kuswantoro | D11: 1000000 | E11: =SUMIF('cth sp'!$M$9:$M$107,B11,'cth sp'!$N$9:$N$107) -> 0 | F11: =SUMIF('cth sp'!$M$9:$M$107,B11,'cth sp'!$O$9:$O$107) -> 0 | G11: =SUMIF('cth sp'!$M$114:$M$158,B11,'cth sp'!$N$114:$N$158) -> 0 | H11: =SUMIF('cth sp'!$M$114:$M$158,B11,'cth sp'!$O$114:$O$158) -> 0 | I11: =SUMIF('cth sp'!$M$159:$M$389,B11,'cth sp'!$N$159:$N$389) -> 0 | J11: =SUMIF('cth sp'!$M$159:$M$389,B11,'cth sp'!$O$159:$O$389) -> 0 | K11: =E11+G11+I11 -> 0 | L11: =F11+H11+J11 -> 0 | M11: =D11+K11-L11 -> 1000000 | P11: 90000 | Q11: 20000 | R11: 30000 | S11: =SUM(O11:R11) -> 140000 | T11: 140000
A12: 3 | B12: A-003 | C12: Agus Ain | D12: 0 | E12: =SUMIF('cth sp'!$M$9:$M$107,B12,'cth sp'!$N$9:$N$107) -> 0 | F12: =SUMIF('cth sp'!$M$9:$M$107,B12,'cth sp'!$O$9:$O$107) -> 0 | G12: =SUMIF('cth sp'!$M$114:$M$158,B12,'cth sp'!$N$114:$N$158) -> 0 | H12: =SUMIF('cth sp'!$M$114:$M$158,B12,'cth sp'!$O$114:$O$158) -> 0 | I12: =SUMIF('cth sp'!$M$159:$M$389,B12,'cth sp'!$N$159:$N$389) -> 0 | J12: =SUMIF('cth sp'!$M$159:$M$389,B12,'cth sp'!$O$159:$O$389) -> 0 | K12: =E12+G12+I12 -> 0 | L12: =F12+H12+J12 -> 0 | M12: =D12+K12-L12 -> 0 | O12: 1000000 | S12: =SUM(O12:R12) -> 1000000
A13: 4 | B13: A-004 | C13: Alimah | D13: 1000000 | E13: =SUMIF('cth sp'!$M$9:$M$107,B13,'cth sp'!$N$9:$N$107) -> 0 | F13: =SUMIF('cth sp'!$M$9:$M$107,B13,'cth sp'!$O$9:$O$107) -> 0 | G13: =SUMIF('cth sp'!$M$114:$M$158,B13,'cth sp'!$N$114:$N$158) -> 0 | H13: =SUMIF('cth sp'!$M$114:$M$158,B13,'cth sp'!$O$114:$O$158) -> 0 | I13: =SUMIF('cth sp'!$M$159:$M$389,B13,'cth sp'!$N$159:$N$389) -> 0 | J13: =SUMIF('cth sp'!$M$159:$M$389,B13,'cth sp'!$O$159:$O$389) -> 0 | K13: =E13+G13+I13 -> 0 | L13: =F13+H13+J13 -> 0 | M13: =D13+K13-L13 -> 1000000 | S13: =SUM(O13:R13) -> 0
A14: 5 | B14: A-005 | C14: Tri Yuliarsih | D14: 0 | E14: =SUMIF('cth sp'!$M$9:$M$107,B14,'cth sp'!$N$9:$N$107) -> 0 | F14: =SUMIF('cth sp'!$M$9:$M$107,B14,'cth sp'!$O$9:$O$107) -> 0 | G14: =SUMIF('cth sp'!$M$114:$M$158,B14,'cth sp'!$N$114:$N$158) -> 0 | H14: =SUMIF('cth sp'!$M$114:$M$158,B14,'cth sp'!$O$114:$O$158) -> 0 | I14: =SUMIF('cth sp'!$M$159:$M$389,B14,'cth sp'!$N$159:$N$389) -> 0 | J14: =SUMIF('cth sp'!$M$159:$M$389,B14,'cth sp'!$O$159:$O$389) -> 0 | K14: =E14+G14+I14 -> 0 | L14: =F14+H14+J14 -> 0 | M14: =D14+K14-L14 -> 0 | P14: =90000*2 -> 180000 | Q14: 40000 | R14: 60000 | S14: =SUM(O14:R14) -> 280000 | T14: 140000
A15: 6 | B15: A-006 | C15: Kuswinarti | D15: 1000000 | E15: =SUMIF('cth sp'!$M$9:$M$107,B15,'cth sp'!$N$9:$N$107) -> 1000000 | F15: =SUMIF('cth sp'!$M$9:$M$107,B15,'cth sp'!$O$9:$O$107) -> 1000000 | G15: =SUMIF('cth sp'!$M$114:$M$158,B15,'cth sp'!$N$114:$N$158) -> 0 | H15: =SUMIF('cth sp'!$M$114:$M$158,B15,'cth sp'!$O$114:$O$158) -> 0 | I15: =SUMIF('cth sp'!$M$159:$M$389,B15,'cth sp'!$N$159:$N$389) -> 0 | J15: =SUMIF('cth sp'!$M$159:$M$389,B15,'cth sp'!$O$159:$O$389) -> 0 | K15: =E15+G15+I15 -> 1000000 | L15: =F15+H15+J15 -> 1000000 | M15: =D15+K15-L15 -> 1000000 | P15: 90000 | Q15: 20000 | R15: 30000 | S15: =SUM(O15:R15) -> 140000 | T15: 140000
A16: 7 | B16: A-007 | C16: Hariyanto | D16: 1000000 | E16: =SUMIF('cth sp'!$M$9:$M$107,B16,'cth sp'!$N$9:$N$107) -> 0 | F16: =SUMIF('cth sp'!$M$9:$M$107,B16,'cth sp'!$O$9:$O$107) -> 0 | G16: =SUMIF('cth sp'!$M$114:$M$158,B16,'cth sp'!$N$114:$N$158) -> 0 | H16: =SUMIF('cth sp'!$M$114:$M$158,B16,'cth sp'!$O$114:$O$158) -> 0 | I16: =SUMIF('cth sp'!$M$159:$M$389,B16,'cth sp'!$N$159:$N$389) -> 0 | J16: =SUMIF('cth sp'!$M$159:$M$389,B16,'cth sp'!$O$159:$O$389) -> 0 | K16: =E16+G16+I16 -> 0 | L16: =F16+H16+J16 -> 0 | M16: =D16+K16-L16 -> 1000000 | P16: 90000 | Q16: 20000 | R16: 30000 | S16: =SUM(O16:R16) -> 140000
A17: 8 | B17: A-008 | C17: Giyanto | D17: 2000000 | E17: =SUMIF('cth sp'!$M$9:$M$107,B17,'cth sp'!$N$9:$N$107) -> 0 | F17: =SUMIF('cth sp'!$M$9:$M$107,B17,'cth sp'!$O$9:$O$107) -> 0 | G17: =SUMIF('cth sp'!$M$114:$M$158,B17,'cth sp'!$N$114:$N$158) -> 0 | H17: =SUMIF('cth sp'!$M$114:$M$158,B17,'cth sp'!$O$114:$O$158) -> 1000000 | I17: =SUMIF('cth sp'!$M$159:$M$389,B17,'cth sp'!$N$159:$N$389) -> 0 | J17: =SUMIF('cth sp'!$M$159:$M$389,B17,'cth sp'!$O$159:$O$389) -> 0 | K17: =E17+G17+I17 -> 0 | L17: =F17+H17+J17 -> 1000000 | M17: =D17+K17-L17 -> 1000000 | P17: 90000 | Q17: 20000 | R17: 30000 | S17: =SUM(O17:R17) -> 140000 | T17: 140000
A18: 9 | B18: A-009 | C18: Imroatus Sholichah | D18: 0 | E18: =SUMIF('cth sp'!$M$9:$M$107,B18,'cth sp'!$N$9:$N$107) -> 0 | F18: =SUMIF('cth sp'!$M$9:$M$107,B18,'cth sp'!$O$9:$O$107) -> 0 | G18: =SUMIF('cth sp'!$M$114:$M$158,B18,'cth sp'!$N$114:$N$158) -> 0 | H18: =SUMIF('cth sp'!$M$114:$M$158,B18,'cth sp'!$O$114:$O$158) -> 0 | I18: =SUMIF('cth sp'!$M$159:$M$389,B18,'cth sp'!$N$159:$N$389) -> 0 | J18: =SUMIF('cth sp'!$M$159:$M$389,B18,'cth sp'!$O$159:$O$389) -> 0 | K18: =E18+G18+I18 -> 0 | L18: =F18+H18+J18 -> 0 | M18: =D18+K18-L18 -> 0 | S18: =SUM(O18:R18) -> 0
A19: 10 | B19: A-010 | C19: Teguh Prasetya | D19: 0 | E19: =SUMIF('cth sp'!$M$9:$M$107,B19,'cth sp'!$N$9:$N$107) -> 0 | F19: =SUMIF('cth sp'!$M$9:$M$107,B19,'cth sp'!$O$9:$O$107) -> 0 | G19: =SUMIF('cth sp'!$M$114:$M$158,B19,'cth sp'!$N$114:$N$158) -> 0 | H19: =SUMIF('cth sp'!$M$114:$M$158,B19,'cth sp'!$O$114:$O$158) -> 0 | I19: =SUMIF('cth sp'!$M$159:$M$389,B19,'cth sp'!$N$159:$N$389) -> 0 | J19: =SUMIF('cth sp'!$M$159:$M$389,B19,'cth sp'!$O$159:$O$389) -> 0 | K19: =E19+G19+I19 -> 0 | L19: =F19+H19+J19 -> 0 | M19: =D19+K19-L19 -> 0 | O19: 835000 | S19: =SUM(O19:R19) -> 835000
A20: 11 | B20: A-011 | C20: Djayos/sami | D20: 1000000 | E20: =SUMIF('cth sp'!$M$9:$M$107,B20,'cth sp'!$N$9:$N$107) -> 0 | F20: =SUMIF('cth sp'!$M$9:$M$107,B20,'cth sp'!$O$9:$O$107) -> 0 | G20: =SUMIF('cth sp'!$M$114:$M$158,B20,'cth sp'!$N$114:$N$158) -> 0 | H20: =SUMIF('cth sp'!$M$114:$M$158,B20,'cth sp'!$O$114:$O$158) -> 0 | I20: =SUMIF('cth sp'!$M$159:$M$389,B20,'cth sp'!$N$159:$N$389) -> 0 | J20: =SUMIF('cth sp'!$M$159:$M$389,B20,'cth sp'!$O$159:$O$389) -> 0 | K20: =E20+G20+I20 -> 0 | L20: =F20+H20+J20 -> 0 | M20: =D20+K20-L20 -> 1000000 | P20: 90000 | Q20: 20000 | R20: 30000 | S20: =SUM(O20:R20) -> 140000 | T20: 140000
A21: 12 | B21: A-012 | C21: Sutriman | D21: 1000000 | E21: =SUMIF('cth sp'!$M$9:$M$107,B21,'cth sp'!$N$9:$N$107) -> 0 | F21: =SUMIF('cth sp'!$M$9:$M$107,B21,'cth sp'!$O$9:$O$107) -> 0 | G21: =SUMIF('cth sp'!$M$114:$M$158,B21,'cth sp'!$N$114:$N$158) -> 0 | H21: =SUMIF('cth sp'!$M$114:$M$158,B21,'cth sp'!$O$114:$O$158) -> 0 | I21: =SUMIF('cth sp'!$M$159:$M$389,B21,'cth sp'!$N$159:$N$389) -> 0 | J21: =SUMIF('cth sp'!$M$159:$M$389,B21,'cth sp'!$O$159:$O$389) -> 0 | K21: =E21+G21+I21 -> 0 | L21: =F21+H21+J21 -> 0 | M21: =D21+K21-L21 -> 1000000 | P21: 90000 | Q21: 20000 | R21: 30000 | S21: =SUM(O21:R21) -> 140000 | T21: 140000
A22: 13 | B22: A-013 | C22: Sasdji Abdullah | D22: 0 | E22: =SUMIF('cth sp'!$M$9:$M$107,B22,'cth sp'!$N$9:$N$107) -> 0 | F22: =SUMIF('cth sp'!$M$9:$M$107,B22,'cth sp'!$O$9:$O$107) -> 0 | G22: =SUMIF('cth sp'!$M$114:$M$158,B22,'cth sp'!$N$114:$N$158) -> 0 | H22: =SUMIF('cth sp'!$M$114:$M$158,B22,'cth sp'!$O$114:$O$158) -> 0 | I22: =SUMIF('cth sp'!$M$159:$M$389,B22,'cth sp'!$N$159:$N$389) -> 0 | J22: =SUMIF('cth sp'!$M$159:$M$389,B22,'cth sp'!$O$159:$O$389) -> 0 | K22: =E22+G22+I22 -> 0 | L22: =F22+H22+J22 -> 0 | M22: =D22+K22-L22 -> 0 | S22: =SUM(O22:R22) -> 0
A23: 14 | B23: A-014 | C23: M. Hadi Praitno | D23: 1000000 | E23: =SUMIF('cth sp'!$M$9:$M$107,B23,'cth sp'!$N$9:$N$107) -> 0 | F23: =SUMIF('cth sp'!$M$9:$M$107,B23,'cth sp'!$O$9:$O$107) -> 0 | G23: =SUMIF('cth sp'!$M$114:$M$158,B23,'cth sp'!$N$114:$N$158) -> 0 | H23: =SUMIF('cth sp'!$M$114:$M$158,B23,'cth sp'!$O$114:$O$158) -> 0 | I23: =SUMIF('cth sp'!$M$159:$M$389,B23,'cth sp'!$N$159:$N$389) -> 0 | J23: =SUMIF('cth sp'!$M$159:$M$389,B23,'cth sp'!$O$159:$O$389) -> 0 | K23: =E23+G23+I23 -> 0 | L23: =F23+H23+J23 -> 0 | M23: =D23+K23-L23 -> 1000000 | S23: =SUM(O23:R23) -> 0
A24: 15 | B24: A-015 | C24: Anwar Wibisono | D24: 1000000 | E24: =SUMIF('cth sp'!$M$9:$M$107,B24,'cth sp'!$N$9:$N$107) -> 1000000 | F24: =SUMIF('cth sp'!$M$9:$M$107,B24,'cth sp'!$O$9:$O$107) -> 1000000 | G24: =SUMIF('cth sp'!$M$114:$M$158,B24,'cth sp'!$N$114:$N$158) -> 0 | H24: =SUMIF('cth sp'!$M$114:$M$158,B24,'cth sp'!$O$114:$O$158) -> 0 | I24: =SUMIF('cth sp'!$M$159:$M$389,B24,'cth sp'!$N$159:$N$389) -> 0 | J24: =SUMIF('cth sp'!$M$159:$M$389,B24,'cth sp'!$O$159:$O$389) -> 0 | K24: =E24+G24+I24 -> 1000000 | L24: =F24+H24+J24 -> 1000000 | M24: =D24+K24-L24 -> 1000000 | S24: =SUM(O24:R24) -> 0
A25: 16 | B25: A-016 | C25: Choirul Anwar | D25: 0 | E25: =SUMIF('cth sp'!$M$9:$M$107,B25,'cth sp'!$N$9:$N$107) -> 0 | F25: =SUMIF('cth sp'!$M$9:$M$107,B25,'cth sp'!$O$9:$O$107) -> 0 | G25: =SUMIF('cth sp'!$M$114:$M$158,B25,'cth sp'!$N$114:$N$158) -> 0 | H25: =SUMIF('cth sp'!$M$114:$M$158,B25,'cth sp'!$O$114:$O$158) -> 0 | I25: =SUMIF('cth sp'!$M$159:$M$389,B25,'cth sp'!$N$159:$N$389) -> 0 | J25: =SUMIF('cth sp'!$M$159:$M$389,B25,'cth sp'!$O$159:$O$389) -> 0 | K25: =E25+G25+I25 -> 0 | L25: =F25+H25+J25 -> 0 | M25: =D25+K25-L25 -> 0 | P25: 90000 | Q25: 20000 | R25: 30000 | S25: =SUM(O25:R25) -> 140000 | T25: 140000
A26: 17 | B26: A-017 | C26: Towardi | D26: 1000000 | E26: =SUMIF('cth sp'!$M$9:$M$107,B26,'cth sp'!$N$9:$N$107) -> 0 | F26: =SUMIF('cth sp'!$M$9:$M$107,B26,'cth sp'!$O$9:$O$107) -> 0 | G26: =SUMIF('cth sp'!$M$114:$M$158,B26,'cth sp'!$N$114:$N$158) -> 0 | H26: =SUMIF('cth sp'!$M$114:$M$158,B26,'cth sp'!$O$114:$O$158) -> 0 | I26: =SUMIF('cth sp'!$M$159:$M$389,B26,'cth sp'!$N$159:$N$389) -> 0 | J26: =SUMIF('cth sp'!$M$159:$M$389,B26,'cth sp'!$O$159:$O$389) -> 0 | K26: =E26+G26+I26 -> 0 | L26: =F26+H26+J26 -> 0 | M26: =D26+K26-L26 -> 1000000 | S26: =SUM(O26:R26) -> 0
A27: 18 | B27: A-018 | C27: Choriyah | D27: 1000000 | E27: =SUMIF('cth sp'!$M$9:$M$107,B27,'cth sp'!$N$9:$N$107) -> 0 | F27: =SUMIF('cth sp'!$M$9:$M$107,B27,'cth sp'!$O$9:$O$107) -> 0 | G27: =SUMIF('cth sp'!$M$114:$M$158,B27,'cth sp'!$N$114:$N$158) -> 0 | H27: =SUMIF('cth sp'!$M$114:$M$158,B27,'cth sp'!$O$114:$O$158) -> 0 | I27: =SUMIF('cth sp'!$M$159:$M$389,B27,'cth sp'!$N$159:$N$389) -> 0 | J27: =SUMIF('cth sp'!$M$159:$M$389,B27,'cth sp'!$O$159:$O$389) -> 0 | K27: =E27+G27+I27 -> 0 | L27: =F27+H27+J27 -> 0 | M27: =D27+K27-L27 -> 1000000 | P27: 90000 | Q27: 20000 | R27: 30000 | S27: =SUM(O27:R27) -> 140000 | T27: 140000
A28: 19 | B28: A-019 | C28: Muji Santoso | D28: 0 | E28: =SUMIF('cth sp'!$M$9:$M$107,B28,'cth sp'!$N$9:$N$107) -> 0 | F28: =SUMIF('cth sp'!$M$9:$M$107,B28,'cth sp'!$O$9:$O$107) -> 0 | G28: =SUMIF('cth sp'!$M$114:$M$158,B28,'cth sp'!$N$114:$N$158) -> 0 | H28: =SUMIF('cth sp'!$M$114:$M$158,B28,'cth sp'!$O$114:$O$158) -> 0 | I28: =SUMIF('cth sp'!$M$159:$M$389,B28,'cth sp'!$N$159:$N$389) -> 0 | J28: =SUMIF('cth sp'!$M$159:$M$389,B28,'cth sp'!$O$159:$O$389) -> 0 | K28: =E28+G28+I28 -> 0 | L28: =F28+H28+J28 -> 0 | M28: =D28+K28-L28 -> 0 | S28: =SUM(O28:R28) -> 0
A29: 20 | B29: A-020 | C29: Muhammad Arifin | D29: 1000000 | E29: =SUMIF('cth sp'!$M$9:$M$107,B29,'cth sp'!$N$9:$N$107) -> 1000000 | F29: =SUMIF('cth sp'!$M$9:$M$107,B29,'cth sp'!$O$9:$O$107) -> 1000000 | G29: =SUMIF('cth sp'!$M$114:$M$158,B29,'cth sp'!$N$114:$N$158) -> 0 | H29: =SUMIF('cth sp'!$M$114:$M$158,B29,'cth sp'!$O$114:$O$158) -> 0 | I29: =SUMIF('cth sp'!$M$159:$M$389,B29,'cth sp'!$N$159:$N$389) -> 0 | J29: =SUMIF('cth sp'!$M$159:$M$389,B29,'cth sp'!$O$159:$O$389) -> 0 | K29: =E29+G29+I29 -> 1000000 | L29: =F29+H29+J29 -> 1000000 | M29: =D29+K29-L29 -> 1000000 | P29: 90000 | Q29: 20000 | R29: 30000 | S29: =SUM(O29:R29) -> 140000
A30: 21 | B30: A-021 | C30: Tri Endah | D30: 1000000 | E30: =SUMIF('cth sp'!$M$9:$M$107,B30,'cth sp'!$N$9:$N$107) -> 0 | F30: =SUMIF('cth sp'!$M$9:$M$107,B30,'cth sp'!$O$9:$O$107) -> 0 | G30: =SUMIF('cth sp'!$M$114:$M$158,B30,'cth sp'!$N$114:$N$158) -> 0 | H30: =SUMIF('cth sp'!$M$114:$M$158,B30,'cth sp'!$O$114:$O$158) -> 0 | I30: =SUMIF('cth sp'!$M$159:$M$389,B30,'cth sp'!$N$159:$N$389) -> 0 | J30: =SUMIF('cth sp'!$M$159:$M$389,B30,'cth sp'!$O$159:$O$389) -> 0 | K30: =E30+G30+I30 -> 0 | L30: =F30+H30+J30 -> 0 | M30: =D30+K30-L30 -> 1000000 | P30: 90000 | Q30: 20000 | R30: 30000 | S30: =SUM(O30:R30) -> 140000
A31: 22 | B31: A-022 | C31: Siti Nur afifa | D31: 2000000 | E31: =SUMIF('cth sp'!$M$9:$M$107,B31,'cth sp'!$N$9:$N$107) -> 1000000 | F31: =SUMIF('cth sp'!$M$9:$M$107,B31,'cth sp'!$O$9:$O$107) -> 1000000 | G31: =SUMIF('cth sp'!$M$114:$M$158,B31,'cth sp'!$N$114:$N$158) -> 0 | H31: =SUMIF('cth sp'!$M$114:$M$158,B31,'cth sp'!$O$114:$O$158) -> 0 | I31: =SUMIF('cth sp'!$M$159:$M$389,B31,'cth sp'!$N$159:$N$389) -> 0 | J31: =SUMIF('cth sp'!$M$159:$M$389,B31,'cth sp'!$O$159:$O$389) -> 0 | K31: =E31+G31+I31 -> 1000000 | L31: =F31+H31+J31 -> 1000000 | M31: =D31+K31-L31 -> 2000000 | P31: 90000 | Q31: 20000 | R31: 30000 | S31: =SUM(O31:R31) -> 140000 | T31: 140000
A32: 23 | B32: A-023 | C32: Susi Sri Wahyuni | D32: 1000000 | E32: =SUMIF('cth sp'!$M$9:$M$107,B32,'cth sp'!$N$9:$N$107) -> 0 | F32: =SUMIF('cth sp'!$M$9:$M$107,B32,'cth sp'!$O$9:$O$107) -> 0 | G32: =SUMIF('cth sp'!$M$114:$M$158,B32,'cth sp'!$N$114:$N$158) -> 0 | H32: =SUMIF('cth sp'!$M$114:$M$158,B32,'cth sp'!$O$114:$O$158) -> 0 | I32: =SUMIF('cth sp'!$M$159:$M$389,B32,'cth sp'!$N$159:$N$389) -> 0 | J32: =SUMIF('cth sp'!$M$159:$M$389,B32,'cth sp'!$O$159:$O$389) -> 0 | K32: =E32+G32+I32 -> 0 | L32: =F32+H32+J32 -> 0 | M32: =D32+K32-L32 -> 1000000 | P32: 90000 | Q32: 20000 | R32: 30000 | S32: =SUM(O32:R32) -> 140000 | T32: 140000
A33: 24 | B33: A-024 | C33: Hari Bayudi | D33: 1000000 | E33: =SUMIF('cth sp'!$M$9:$M$107,B33,'cth sp'!$N$9:$N$107) -> 1000000 | F33: =SUMIF('cth sp'!$M$9:$M$107,B33,'cth sp'!$O$9:$O$107) -> 1000000 | G33: =SUMIF('cth sp'!$M$114:$M$158,B33,'cth sp'!$N$114:$N$158) -> 0 | H33: =SUMIF('cth sp'!$M$114:$M$158,B33,'cth sp'!$O$114:$O$158) -> 0 | I33: =SUMIF('cth sp'!$M$159:$M$389,B33,'cth sp'!$N$159:$N$389) -> 0 | J33: =SUMIF('cth sp'!$M$159:$M$389,B33,'cth sp'!$O$159:$O$389) -> 0 | K33: =E33+G33+I33 -> 1000000 | L33: =F33+H33+J33 -> 1000000 | M33: =D33+K33-L33 -> 1000000 | S33: =SUM(O33:R33) -> 0
A34: 25 | B34: A-025 | C34: Ilham Hendrik | D34: 1000000 | E34: =SUMIF('cth sp'!$M$9:$M$107,B34,'cth sp'!$N$9:$N$107) -> 1000000 | F34: =SUMIF('cth sp'!$M$9:$M$107,B34,'cth sp'!$O$9:$O$107) -> 1000000 | G34: =SUMIF('cth sp'!$M$114:$M$158,B34,'cth sp'!$N$114:$N$158) -> 0 | H34: =SUMIF('cth sp'!$M$114:$M$158,B34,'cth sp'!$O$114:$O$158) -> 0 | I34: =SUMIF('cth sp'!$M$159:$M$389,B34,'cth sp'!$N$159:$N$389) -> 0 | J34: =SUMIF('cth sp'!$M$159:$M$389,B34,'cth sp'!$O$159:$O$389) -> 0 | K34: =E34+G34+I34 -> 1000000 | L34: =F34+H34+J34 -> 1000000 | M34: =D34+K34-L34 -> 1000000 | P34: 90000 | Q34: 20000 | R34: 30000 | S34: =SUM(O34:R34) -> 140000 | T34: 140000
A35: 26 | B35: A-026 | C35: Abdul Rochman | D35: 1000000 | E35: =SUMIF('cth sp'!$M$9:$M$107,B35,'cth sp'!$N$9:$N$107) -> 0 | F35: =SUMIF('cth sp'!$M$9:$M$107,B35,'cth sp'!$O$9:$O$107) -> 0 | G35: =SUMIF('cth sp'!$M$114:$M$158,B35,'cth sp'!$N$114:$N$158) -> 0 | H35: =SUMIF('cth sp'!$M$114:$M$158,B35,'cth sp'!$O$114:$O$158) -> 0 | I35: =SUMIF('cth sp'!$M$159:$M$389,B35,'cth sp'!$N$159:$N$389) -> 0 | J35: =SUMIF('cth sp'!$M$159:$M$389,B35,'cth sp'!$O$159:$O$389) -> 0 | K35: =E35+G35+I35 -> 0 | L35: =F35+H35+J35 -> 0 | M35: =D35+K35-L35 -> 1000000 | S35: =SUM(O35:R35) -> 0
A36: 27 | B36: A-027 | C36: Bagus Setiawan | D36: 1000000 | E36: =SUMIF('cth sp'!$M$9:$M$107,B36,'cth sp'!$N$9:$N$107) -> 1000000 | F36: =SUMIF('cth sp'!$M$9:$M$107,B36,'cth sp'!$O$9:$O$107) -> 1000000 | G36: =SUMIF('cth sp'!$M$114:$M$158,B36,'cth sp'!$N$114:$N$158) -> 1000000 | H36: =SUMIF('cth sp'!$M$114:$M$158,B36,'cth sp'!$O$114:$O$158) -> 1000000 | I36: =SUMIF('cth sp'!$M$159:$M$389,B36,'cth sp'!$N$159:$N$389) -> 0 | J36: =SUMIF('cth sp'!$M$159:$M$389,B36,'cth sp'!$O$159:$O$389) -> 0 | K36: =E36+G36+I36 -> 2000000 | L36: =F36+H36+J36 -> 2000000 | M36: =D36+K36-L36 -> 1000000 | P36: 90000 | Q36: 20000 | R36: 30000 | S36: =SUM(O36:R36) -> 140000 | T36: 140000
A37: 28 | B37: A-028 | C37: Dwi Cahyorini | D37: 1000000 | E37: =SUMIF('cth sp'!$M$9:$M$107,B37,'cth sp'!$N$9:$N$107) -> 0 | F37: =SUMIF('cth sp'!$M$9:$M$107,B37,'cth sp'!$O$9:$O$107) -> 0 | G37: =SUMIF('cth sp'!$M$114:$M$158,B37,'cth sp'!$N$114:$N$158) -> 0 | H37: =SUMIF('cth sp'!$M$114:$M$158,B37,'cth sp'!$O$114:$O$158) -> 0 | I37: =SUMIF('cth sp'!$M$159:$M$389,B37,'cth sp'!$N$159:$N$389) -> 0 | J37: =SUMIF('cth sp'!$M$159:$M$389,B37,'cth sp'!$O$159:$O$389) -> 0 | K37: =E37+G37+I37 -> 0 | L37: =F37+H37+J37 -> 0 | M37: =D37+K37-L37 -> 1000000 | P37: 90000 | Q37: 20000 | R37: 30000 | S37: =SUM(O37:R37) -> 140000
A38: 29 | B38: A-029 | C38: Mamik Kurianawati | D38: 1000000 | E38: =SUMIF('cth sp'!$M$9:$M$107,B38,'cth sp'!$N$9:$N$107) -> 0 | F38: =SUMIF('cth sp'!$M$9:$M$107,B38,'cth sp'!$O$9:$O$107) -> 0 | G38: =SUMIF('cth sp'!$M$114:$M$158,B38,'cth sp'!$N$114:$N$158) -> 0 | H38: =SUMIF('cth sp'!$M$114:$M$158,B38,'cth sp'!$O$114:$O$158) -> 0 | I38: =SUMIF('cth sp'!$M$159:$M$389,B38,'cth sp'!$N$159:$N$389) -> 0 | J38: =SUMIF('cth sp'!$M$159:$M$389,B38,'cth sp'!$O$159:$O$389) -> 0 | K38: =E38+G38+I38 -> 0 | L38: =F38+H38+J38 -> 0 | M38: =D38+K38-L38 -> 1000000 | S38: =SUM(O38:R38) -> 0
A39: 30 | B39: A-030 | C39: Era puspitasari | D39: 1000000 | E39: =SUMIF('cth sp'!$M$9:$M$107,B39,'cth sp'!$N$9:$N$107) -> 0 | F39: =SUMIF('cth sp'!$M$9:$M$107,B39,'cth sp'!$O$9:$O$107) -> 0 | G39: =SUMIF('cth sp'!$M$114:$M$158,B39,'cth sp'!$N$114:$N$158) -> 0 | H39: =SUMIF('cth sp'!$M$114:$M$158,B39,'cth sp'!$O$114:$O$158) -> 0 | I39: =SUMIF('cth sp'!$M$159:$M$389,B39,'cth sp'!$N$159:$N$389) -> 0 | J39: =SUMIF('cth sp'!$M$159:$M$389,B39,'cth sp'!$O$159:$O$389) -> 0 | K39: =E39+G39+I39 -> 0 | L39: =F39+H39+J39 -> 0 | M39: =D39+K39-L39 -> 1000000 | S39: =SUM(O39:R39) -> 0
A40: 31 | B40: A-031 | C40: Sutjipto | D40: 1000000 | E40: =SUMIF('cth sp'!$M$9:$M$107,B40,'cth sp'!$N$9:$N$107) -> 1000000 | F40: =SUMIF('cth sp'!$M$9:$M$107,B40,'cth sp'!$O$9:$O$107) -> 1000000 | G40: =SUMIF('cth sp'!$M$114:$M$158,B40,'cth sp'!$N$114:$N$158) -> 0 | H40: =SUMIF('cth sp'!$M$114:$M$158,B40,'cth sp'!$O$114:$O$158) -> 0 | I40: =SUMIF('cth sp'!$M$159:$M$389,B40,'cth sp'!$N$159:$N$389) -> 0 | J40: =SUMIF('cth sp'!$M$159:$M$389,B40,'cth sp'!$O$159:$O$389) -> 0 | K40: =E40+G40+I40 -> 1000000 | L40: =F40+H40+J40 -> 1000000 | M40: =D40+K40-L40 -> 1000000 | S40: =SUM(O40:R40) -> 0
A41: 32 | B41: A-032 | C41: Titi Hari N | D41: 1000000 | E41: =SUMIF('cth sp'!$M$9:$M$107,B41,'cth sp'!$N$9:$N$107) -> 0 | F41: =SUMIF('cth sp'!$M$9:$M$107,B41,'cth sp'!$O$9:$O$107) -> 0 | G41: =SUMIF('cth sp'!$M$114:$M$158,B41,'cth sp'!$N$114:$N$158) -> 0 | H41: =SUMIF('cth sp'!$M$114:$M$158,B41,'cth sp'!$O$114:$O$158) -> 0 | I41: =SUMIF('cth sp'!$M$159:$M$389,B41,'cth sp'!$N$159:$N$389) -> 0 | J41: =SUMIF('cth sp'!$M$159:$M$389,B41,'cth sp'!$O$159:$O$389) -> 0 | K41: =E41+G41+I41 -> 0 | L41: =F41+H41+J41 -> 0 | M41: =D41+K41-L41 -> 1000000 | P41: 90000 | Q41: 20000 | R41: 30000 | S41: =SUM(O41:R41) -> 140000 | T41: 140000
...

Sheet CTH lapak
A1: CATATAN HARIAN
A2: BUMDES "BAROKAH" Balongbesuk Diwek Jombang
A3: ='sum sp'!B3 -> TAHUN ANGGARAN 2025
A4: UNIT JASA LAPAK | H4: 3253850
H5: =H4-100000 -> 3153850
A6: TANGGAL | B6: CODE | C6: Penerima | D6: URAIAN | E6: UMUM | G6: KAS | J6: BANK | M6: HUTANG SEWA LAPAK
E7: MASUK | F7: KELUAR | G7: MASUK | H7: KELUAR | I7: SISA | J7: MASUK | K7: KELUAR | L7: SISA | N7: MASUK | O7: KELUAR | P7: SISA
A8: 45658 | D8: Saldo awal tahun 2025 | E8: 3253850 | G8: 3153850 | I8: =G8-H8 -> 3153850 | J8: 100000 | L8: =J8-K8 -> 100000 | P8: =N8-O8 -> 0
A9: 45658 | B9: 5102 | D9: Transportasi | F9: 300000 | H9: 300000 | I9: =I8+G9-H9 -> 2853850 | L9: =L8+J9-K9 -> 100000 | P9: =P8+N9-O9 -> 0
B10: 5109 | D10: Koreksi laporan tahun 2024 | F10: 2434850 | H10: 2434850 | I10: =I9+G10-H10 -> 419000
A11: 7/Maret/2025 | B11: 2001 | C11: SUGIATI | D11: pendapatan sewa lapak 25 (tahun 2024) | E11: 1000000 | G11: 1000000 | I11: =I10+G11-H11 -> 1419000 | L11: =#REF!+J11-K11 -> #REF!
A12: 7/Maret/2025 | B12: 2001 | C12: H. Abd Hamid Muzaki | D12: pendapatan sewa lapakH. Abd Hamid Muzaki | E12: 1500000 | G12: 1500000 | I12: =I11+G12-H12 -> 2919000 | L12: =L11+J12-K12 -> #REF!
A13: 20/Maret/2025 | B13: 5201 | C13: Dodik | D13: PemaSangan Meteran Listrik Balong | F13: 1200000 | H13: 1200000 | I13: =I12+G13-H13 -> 1719000 | L13: =L12+J13-K13 -> #REF!
A14: 04- juni 2025 | B14: 2001 | C14: SUSILO | D14: Pendapatan Sewa Lapak 43, 44 | E14: 4000000 | G14: 4000000 | I14: =I13+G14-H14 -> 5719000 | L14: =L13+J14-K14 -> #REF!
A15: 21- Agustus 2025 | B15: 2001 | C15: SUWONO | D15: Pendapatan Sewa Lapak 13, | E15: 1000000 | G15: 1000000 | I15: =I14+G15-H15 -> 6719000 | L15: =L14+J15-K15 -> #REF!
A16: 1- seeptember 2025 | B16: 5102 | D16: Biaya Study Banding Ke tambakrejo | F16: 1000000 | H16: 1000000 | I16: =I15+G16-H16 -> 5719000 | L16: =L15+J16-K16 -> #REF!
A17: 21-Agustus- 2025 | B17: 2001 | C17: DODIK | D17: Pendapatan sewa laapak 1,2, 3 | E17: 3000000 | G17: 3000000 | I17: =I16+G17-H17 -> 8719000 | L17: =L16+J17-K17 -> #REF!
A18: 6- seeptember 2025 | B18: 2001 | C18: MUNJIROH | D18: Pendapatan sewa lapak 27, 28 (tahun 2024) | E18: 2000000 | G18: 2000000 | I18: =I17+G18-H18 -> 10719000 | L18: =L17+J18-K18 -> #REF!
A19: 11- seeptember 2025 | B19: 2001 | C19: RISTAKUL J | D19: Pendapatan sewa lapak 20 (tahun 2024) | E19: 1000000 | G19: 1000000 | I19: =I18+G19-H19 -> 11719000 | L19: =L18+J19-K19 -> #REF!
A20: 18-10-2025 | B20: 2001 | C20: ABD. HAMID | D20: Pendapatan sewa lapak 23, 24 (tahun KEDUA) | E20: 3000000 | G20: 3000000 | I20: =I19+G20-H20 -> 14719000 | L20: =L19+J20-K20 -> #REF!
B21: 2001 | C21: es batu | D21: Pendapatan sewa lapak 11, 12 (tahun ke 2) | E21: 2000000 | G21: 2000000 | I21: =I20+G21-H21 -> 16719000
B22: 2001 | C22: DODIK B | D22: Pendapatan sewa lapak 4, 5 | E22: 2000000 | G22: 2000000 | I22: =I21+G22-H22 -> 18719000
B23: 2001 | C23: EKA F | D23: Pendapatan sewa lapak 35, 36, 37 | E23: 3000000 | G23: 3000000 | I23: =I22+G23-H23 -> 21719000 | L23: =L20+J23-K23 -> #REF!
B24: 5101 | C24: Arifin | D24: INSENTIF Pengelolah LapaK | F24: 6515700 | H24: 6515700 | I24: =I23+G24-H24 -> 15203300
B25: STR | C25: Mamik | D25: setor ke BUMDES | F25: 15203300 | H25: 15203300 | I25: =I24+G25-H25 -> 0 | L25: =L23+J25-K25 -> #REF!
D26: Bulan ini | E26: =SUM(E9:E25) -> 23500000 | F26: =SUM(F9:F25) -> 26653850 | G26: =SUM(G9:G25) -> 23500000 | H26: =SUM(H9:H25) -> 26653850 | J26: =SUM(J9:J25) -> 0 | K26: =SUM(K9:K25) -> 0 | N26: =SUM(N9:N25) -> 0 | O26: =SUM(O9:O25) -> 0
D27: Sampai bulan ini | E27: =E8+E26 -> 26753850 | F27: =F8+F26 -> 26653850 | G27: =G8+G26 -> 26653850 | H27: =H8+H26 -> 26653850 | J27: =J8+J26 -> 100000 | K27: =K8+K26 -> 0 | N27: =N8+N26 -> 0 | O27: =O8+O26 -> 0
D28: SALDO | E28: =E27-F27 -> 100000 | G28: =G27-H27 -> 0 | J28: =J27-K27 -> 100000 | N28: =N27-O27 -> 0

Sheet SUM LAPAK
A1: CASH FLOW
A2: BUMDES "BAROKAH" BALONGBESUK DIWEK JOMBANG
A3: TAHUN ANGGARAN 2024
A5: UNIT USAHA LAPAK UMKM
A7: CODE | B7: URAIAN | C7: TAHUN 2022 | D7: TOTAL
A10: 1000 | B10: DANA AWAL | D10: =SUM(C10:C10) -> 0
A12: 2000 | B12: PENDAPATAN | C12: =SUM(C13:C13) -> 23500000 | D12: =SUM(D13:D14) -> 23500000
A13: 2001 | B13: Pendapatan Pengelolaan Lapak | C13: =SUMIF('CTH lapak'!$B$8:$B$25,A13,'CTH lapak'!$E$8:$E$25) -> 23500000 | D13: =SUM(C13:C13) -> 23500000
A14: 2009 | B14: Pendapatan sumbangan | C14: =SUMIF('CTH lapak'!$B$8:$B$25,A14,'CTH lapak'!$E$8:$E$25) -> 0 | D14: =SUM(C14:C14) -> 0
A15: 3000 | B15: PIUTANG KOMITMENT | C15: =SUM(C16:C16) -> 0 | D15: =SUM(D16:D16) -> 0
A16: 3001 | B16: Piutang Komitment Sewa Lapak | C16: =SUMIF('CTH lapak'!$B$8:$B$25,A16,'CTH lapak'!$E$8:$E$25) -> 0 | D16: =SUM(C16:C16) -> 0
B18: TOTAL MASUK | C18: =C10+C12+C15 -> 23500000 | D18: =D10+D12+D15 -> 23500000
A20: 5000 | B20: BELANJA | C20: =C21 -> 10250550 | D20: =D21 -> 10250550
A21: 5100 | B21: Operasional | C21: =SUM(C22:C29) -> 10250550 | D21: =SUM(D22:D29) -> 10250550
A22: 5101 | B22: Gaji/Honor /Insentif Pegawai | C22: =SUMIF('CTH lapak'!$B$8:$B$25,A22,'CTH lapak'!$F$8:$F$25) -> 6515700 | D22: =SUM(C22) -> 6515700
A23: 5102 | B23: Transportasi | C23: =SUMIF('CTH lapak'!$B$8:$B$25,A23,'CTH lapak'!$F$8:$F$25) -> 1300000 | D23: =SUM(C23) -> 1300000
A24: 5103 | B24: Peralatan Kebersihan | C24: =SUMIF('CTH lapak'!$B$8:$B$25,A24,'CTH lapak'!$F$8:$F$25) -> 0 | D24: =SUM(C24) -> 0
A25: 5104 | B25: Listrik | C25: =SUMIF('CTH lapak'!$B$8:$B$25,A25,'CTH lapak'!$F$8:$F$25) -> 0 | D25: =SUM(C25) -> 0
A26: 5105 | B26: ATK, Cetak dan Penggandaan | C26: =SUMIF('CTH lapak'!$B$8:$B$25,A26,'CTH lapak'!$F$8:$F$25) -> 0 | D26: =SUM(C26) -> 0
A27: 5106 | B27: Pemetaan Lapak | C27: =SUMIF('CTH lapak'!$B$8:$B$25,A27,'CTH lapak'!$F$8:$F$25) -> 0 | D27: =SUM(C27) -> 0
A28: 5107 | B28: Rapat-Rapat | C28: =SUMIF('CTH lapak'!$B$8:$B$25,A28,'CTH lapak'!$F$8:$F$25) -> 0 | D28: =SUM(C28) -> 0
A29: 5109 | B29: Belanja Lain-Lain | C29: =SUMIF('CTH lapak'!$B$8:$B$25,A29,'CTH lapak'!$F$8:$F$25) -> 2434850 | D29: =SUM(C29) -> 2434850
A31: 5200 | B31: PERLENGKAPAN | C31: =C32 -> 1200000 | D31: =D32 -> 1200000
A32: 5201 | B32: PERLENGKAPAN ELEKTRIK | C32: =SUMIF('CTH lapak'!$B$8:$B$25,A32,'CTH lapak'!$F$8:$F$25) -> 1200000 | D32: =SUM(C32) -> 1200000
C33: =SUMIF('CTH lapak'!$B$8:$B$25,A33,'CTH lapak'!$F$8:$F$25) -> 0
A34: 3000 | B34: PIUTANG | C34: =SUM(C35:C36) -> 0 | D34: =SUM(D35:D36) -> 0
A35: 3001 | B35: Piutang Komitment Sewa Lapak | D35: =SUM(C35) -> 0
A36: 3002 | B36: Piutang Pihak Ke 3 | C36: =SUMIF('CTH lapak'!$B$8:$B$25,A36,'CTH lapak'!$F$8:$F$25) -> 0 | D36: =SUM(C36) -> 0
A38: STR | B38: SETOR KE BENDAHARA | C38: =SUMIF('CTH lapak'!$B$8:$B$25,A38,'CTH lapak'!$F$8:$F$25) -> 15203300 | D38: =SUM(C38) -> 15203300
B39: JUMLAH | C39: =C34+C20+C31+C38 -> 26653850 | D39: =D34+D20+D31+D38 -> 26653850
B40: SURPLUS / DEVISIT | C40: =C18-C39 -> -3153850 | D40: =D18-D39 -> -3153850
B43: MODAL AWAL | C43: 3253850
B44: PENDAPATAN | C44: =D12 -> 23500000
B45: PENGEMBALIAN PIUTANG | C45: =D16 -> 0
B46: TOTAL | C46: =C44+C45 -> 23500000
B48: PENGELUARAN
B50: Operasioal | C50: =D21 -> 10250550
B51: perlengkapan | C51: =D31 -> 1200000
B52: piutang | C52: =D36 -> 0
B53: Setor Ke Bendahara | C53: =D38 -> 15203300
...

Sheet cth sp
A1: =Sheet1!C7 -> " BAROKAH "
A2: =Sheet1!C8 -> Desa Balongbesuk Kecamatan Diwek Kabupaten Jombang
A3: =Sheet1!C4 -> TAHUN ANGGARAN 2025 | N3: 57000000
O4: 62000000 | S4: 2800000
A5: CATATAN HARIAN | O5: 33000000 | S5: 14520000
O6: =SUM(O4:O5) -> 95000000 | S6: =SUM(S4:S5) -> 17320000
A7: TANGGAL | B7: CODE | C7: Penerima | D7: URAIAN | E7: UMUM | G7: KAS | J7: BANK | N7: PIUTANG | Q7: CODE | R7: TABUNGAN
E8: MASUK | F8: KELUAR | G8: MASUK | H8: KELUAR | I8: SISA | J8: MASUK | K8: KELUAR | L8: SISA | N8: MASUK | O8: KELUAR | P8: SISA | R8: MASUK | S8: KELUAR | T8: SISA
A9: 45658 | D9: Saldo awal tahun 2025 | I9: =G9-H9 -> 0 | J9: 0 | L9: =J9-K9 -> 0 | N9: 95000000 | P9: =N9-O9 -> 95000000 | R9: 17320000 | T9: =R9-S9 -> 17320000
A10: 23/05/2025 | B10: 2002 | D10: Pengembalian Uang dari Gapoktan | I10: =I9+G10-H10 -> 0 | L10: =L9+J10-K10 -> 0 | M10: A-000 | P10: =P9+N10-O10 -> 95000000 | T10: =T9+R10-S10 -> 17320000
A11: 20/05/2025 | B11: 2001 | C11: Sutjipto | D11: Pengembalian Pinjaman Masyarakat | E11: 1000000 | G11: 1000000 | I11: =I10+G11-H11 -> 1000000 | L11: =#REF!+J11-K11 -> #REF! | M11: A-031 | O11: 1000000 | P11: =P10+N11-O11 -> 94000000 | T11: =T10+R11-S11 -> 17320000
A12: 20/05/2025 | B12: 2001 | C12: budiono | D12: Pengembalian Pinjaman Masyarakat | E12: 1000000 | G12: 1000000 | I12: =I11+G12-H12 -> 2000000 | L12: =L11+J12-K12 -> #REF! | M12: A-065 | O12: 1000000 | P12: =P11+N12-O12 -> 93000000 | T12: =T11+R12-S12 -> 17320000
A13: 20/05/2025 | B13: 2001 | C13: Anwar | D13: Pengembalian Pinjaman Masyarakat | E13: 1000000 | G13: 1000000 | I13: =I12+G13-H13 -> 3000000 | L13: =L12+J13-K13 -> #REF! | M13: A-015 | O13: 1000000 | P13: =P12+N13-O13 -> 92000000 | T13: =T12+R13-S13 -> 17320000
A14: 20/05/2025 | B14: 2001 | C14: Sunarsih | D14: Pengembalian Pinjaman Masyarakat | E14: 1000000 | G14: 1000000 | I14: =I13+G14-H14 -> 4000000 | L14: =L13+J14-K14 -> #REF! | M14: A-058 | O14: 1000000 | P14: =P13+N14-O14 -> 91000000 | T14: =T13+R14-S14 -> 17320000
A15: 20/05/2025 | B15: 2001 | C15: Vivi Diana | D15: Pengembalian Pinjaman Masyarakat | E15: 2000000 | G15: 2000000 | I15: =I14+G15-H15 -> 6000000 | L15: =L14+J15-K15 -> #REF! | M15: A-044 | O15: 2000000 | P15: =P14+N15-O15 -> 89000000 | T15: =T14+R15-S15 -> 17320000
A16: 20/05/2025 | B16: 2001 | C16: bagus S | D16: Pengembalian Pinjaman Masyarakat | E16: 1000000 | G16: 1000000 | I16: =I15+G16-H16 -> 7000000 | L16: =L15+J16-K16 -> #REF! | M16: A-027 | O16: 1000000 | P16: =P15+N16-O16 -> 88000000 | T16: =T15+R16-S16 -> 17320000
A17: 20/05/2025 | B17: 2001 | C17: warsiti | D17: Pengembalian Pinjaman Masyarakat | E17: 1000000 | G17: 1000000 | I17: =I16+G17-H17 -> 8000000 | L17: =L16+J17-K17 -> #REF! | M17: A-056 | O17: 1000000 | P17: =P16+N17-O17 -> 87000000 | T17: =T16+R17-S17 -> 17320000
A18: 20/05/2025 | B18: 2001 | C18: kamdani | D18: Pengembalian Pinjaman Masyarakat | E18: 1000000 | G18: 1000000 | I18: =I17+G18-H18 -> 9000000 | L18: =L17+J18-K18 -> #REF! | M18: A-040 | O18: 1000000 | P18: =P17+N18-O18 -> 86000000 | T18: =T17+R18-S18 -> 17320000
A19: 20/05/2025 | B19: 2001 | C19: endang | D19: Pengembalian Pinjaman Masyarakat | E19: 1000000 | G19: 1000000 | I19: =I18+G19-H19 -> 10000000 | L19: =L18+J19-K19 -> #REF! | M19: A-062 | O19: 1000000 | P19: =P18+N19-O19 -> 85000000 | T19: =T18+R19-S19 -> 17320000
A20: 20/05/2025 | B20: 2001 | C20: priyo kustanto | D20: Pengembalian Pinjaman Masyarakat | E20: 1000000 | G20: 1000000 | I20: =I19+G20-H20 -> 11000000 | L20: =L19+J20-K20 -> #REF! | M20: A-043 | O20: 1000000 | P20: =P19+N20-O20 -> 84000000 | T20: =T19+R20-S20 -> 17320000
A21: 20/05/2025 | B21: 2001 | C21: kuswinarti | D21: Pengembalian Pinjaman Masyarakat | E21: 1000000 | G21: 1000000 | I21: =I20+G21-H21 -> 12000000 | L21: =L20+J21-K21 -> #REF! | M21: A-006 | O21: 1000000 | P21: =P20+N21-O21 -> 83000000 | T21: =T20+R21-S21 -> 17320000
A22: 20/05/2025 | B22: 2001 | C22: siti nur afifah | D22: Pengembalian Pinjaman Masyarakat | E22: 1000000 | G22: 1000000 | I22: =I21+G22-H22 -> 13000000 | L22: =L21+J22-K22 -> #REF! | M22: A-022 | O22: 1000000 | P22: =P21+N22-O22 -> 82000000 | T22: =T21+R22-S22 -> 17320000
A23: 20/05/2025 | B23: 2001 | C23: siti djayanti | D23: Pengembalian Pinjaman Masyarakat | E23: 1000000 | G23: 1000000 | I23: =I22+G23-H23 -> 14000000 | M23: A-001 | O23: 1000000 | P23: =P22+N23-O23 -> 81000000 | T23: =T22+R23-S23 -> 17320000
A24: 20/05/2025 | B24: 2001 | C24: hari bayudi | D24: Pengembalian Pinjaman Masyarakat | E24: 1000000 | G24: 1000000 | I24: =I23+G24-H24 -> 15000000 | L24: =L22+J24-K24 -> #REF! | M24: A-024 | O24: 1000000 | P24: =P23+N24-O24 -> 80000000 | T24: =T23+R24-S24 -> 17320000
A25: 20/05/2025 | B25: 2001 | C25: lilik indayani | D25: Pengembalian Pinjaman Masyarakat | E25: 1000000 | G25: 1000000 | I25: =I24+G25-H25 -> 16000000 | L25: =L24+J25-K25 -> #REF! | M25: A-060 | O25: 1000000 | P25: =P24+N25-O25 -> 79000000 | T25: =T24+R25-S25 -> 17320000
A26: 20/05/2025 | B26: 2001 | C26: ilham handrik | D26: Pengembalian Pinjaman Masyarakat | E26: 1000000 | G26: 1000000 | I26: =I25+G26-H26 -> 17000000 | M26: A-025 | O26: 1000000 | P26: =P25+N26-O26 -> 78000000 | T26: =T25+R26-S26 -> 17320000
A27: 20/05/2025 | B27: 2001 | C27: M. arifin | D27: Pengembalian Pinjaman Masyarakat | E27: 1000000 | G27: 1000000 | I27: =I26+G27-H27 -> 18000000 | M27: A-020 | O27: 1000000 | P27: =P26+N27-O27 -> 77000000 | T27: =T26+R27-S27 -> 17320000
A28: 20/05/2025 | B28: 2001 | C28: Dwi Astutik | D28: Pengembalian Pinjaman Masyarakat | E28: 1000000 | G28: 1000000 | I28: =I27+G28-H28 -> 19000000 | M28: A-036 | O28: 1000000 | P28: =P27+N28-O28 -> 76000000 | T28: =T27+R28-S28 -> 17320000
A29: 20/05/2025 | B29: 2001 | C29: suparti | D29: Pengembalian Pinjaman Masyarakat | E29: 1000000 | G29: 1000000 | I29: =I28+G29-H29 -> 20000000 | M29: A-057 | O29: 1000000 | P29: =P28+N29-O29 -> 75000000 | T29: =T28+R29-S29 -> 17320000
A30: 20/05/2025 | B30: 4103 | C30: Gapoktan | D30: Pendapatan Jasa dari GAPOKTAN | E30: 600000 | G30: 600000 | I30: =I29+G30-H30 -> 20600000 | P30: =P29+N30-O30 -> 75000000 | T30: =T29+R30-S30 -> 17320000
A31: 20/05/2025 | B31: 2001 | C31: Sutjipto | D31: Penyaluran Pinjaman Masyarakat | F31: 1000000 | H31: 1000000 | I31: =I30+G31-H31 -> 19600000 | M31: A-031 | N31: 1000000 | P31: =P30+N31-O31 -> 76000000 | T31: =T30+R31-S31 -> 17320000
A32: 20/05/2025 | B32: 2001 | C32: budiono | D32: Penyaluran Pinjaman Masyarakat | F32: 1000000 | H32: 1000000 | I32: =I31+G32-H32 -> 18600000 | M32: A-065 | N32: 1000000 | P32: =P31+N32-O32 -> 77000000 | T32: =T31+R32-S32 -> 17320000
A33: 20/05/2025 | B33: 2001 | C33: Anwar | D33: Penyaluran Pinjaman Masyarakat | F33: 1000000 | H33: 1000000 | I33: =I32+G33-H33 -> 17600000 | M33: A-015 | N33: 1000000 | P33: =P32+N33-O33 -> 78000000 | T33: =T32+R33-S33 -> 17320000
A34: 23/05/2025 | B34: 2001 | C34: Sunarsih | D34: Penyaluran Pinjaman Masyarakat | F34: 1000000 | H34: 1000000 | I34: =I33+G34-H34 -> 16600000 | M34: A-058 | N34: 1000000 | P34: =P33+N34-O34 -> 79000000 | T34: =T33+R34-S34 -> 17320000
A35: 23/05/2025 | B35: 2001 | C35: Vivi Diana | D35: Penyaluran Pinjaman Masyarakat | F35: 2000000 | H35: 2000000 | I35: =I34+G35-H35 -> 14600000 | M35: A-044 | N35: 2000000 | P35: =P34+N35-O35 -> 81000000 | T35: =T34+R35-S35 -> 17320000
A36: 23/05/2025 | B36: 2001 | C36: bagus S | D36: Penyaluran Pinjaman Masyarakat | F36: 1000000 | H36: 1000000 | I36: =I35+G36-H36 -> 13600000 | M36: A-027 | N36: 1000000 | P36: =P35+N36-O36 -> 82000000 | T36: =T35+R36-S36 -> 17320000
A37: 23/05/2025 | B37: 2001 | C37: warsiti | D37: Penyaluran Pinjaman Masyarakat | F37: 1000000 | H37: 1000000 | I37: =I36+G37-H37 -> 12600000 | M37: A-056 | N37: 1000000 | P37: =P36+N37-O37 -> 83000000 | T37: =T36+R37-S37 -> 17320000
A38: 23/05/2025 | B38: 2001 | C38: kamdani | D38: Penyaluran Pinjaman Masyarakat | F38: 1000000 | H38: 1000000 | I38: =I37+G38-H38 -> 11600000 | M38: A-040 | N38: 1000000 | P38: =P37+N38-O38 -> 84000000 | T38: =T37+R38-S38 -> 17320000
A39: 23/05/2025 | B39: 2001 | C39: endang | D39: Penyaluran Pinjaman Masyarakat | F39: 1000000 | H39: 1000000 | I39: =I38+G39-H39 -> 10600000 | M39: A-062 | N39: 1000000 | P39: =P38+N39-O39 -> 85000000 | T39: =T38+R39-S39 -> 17320000
A40: 23/05/2025 | B40: 2001 | C40: priyo kustanto | D40: Penyaluran Pinjaman Masyarakat | F40: 1000000 | H40: 1000000 | I40: =I39+G40-H40 -> 9600000 | M40: A-043 | N40: 1000000 | P40: =P39+N40-O40 -> 86000000 | T40: =T39+R40-S40 -> 17320000
...

Sheet cth gEDUNG
A1: CATATAN HARIAN
A2: BUMDES "BAROKAH" Balongbesuk Diwek Jombang
A3: ='sum sp'!B3 -> TAHUN ANGGARAN 2025
A4: UNIT PENGELOLAAN GEDUNG SERBA GUNA | G4: 5457800
A6: TANGGAL | B6: CODE | C6: Penerima | D6: URAIAN | E6: UMUM | G6: KAS | J6: BANK
E7: MASUK | F7: KELUAR | G7: MASUK | H7: KELUAR | I7: SISA | J7: MASUK | K7: KELUAR | L7: SISA
A8: 45658 | D8: Saldo awal tahun 2025 | E8: 5457800 | G8: 5457800 | I8: =G8-H8 -> 5457800 | J8: 0 | L8: =J8-K8 -> 0
A9: 30/01/2025 | B9: 2001 | D9: PB. GSG | E9: 390000 | G9: 390000 | I9: =I8+G9-H9 -> 5847800
A10: 30/01/2025 | B10: 2001 | D10: PB. KKMI | E10: 120000 | G10: 120000 | I10: =I9+G10-H10 -> 5967800 | L10: =L8+J10-K10 -> 0
A11: 30/01/2025 | B11: 2001 | D11: PB. RSNU | E11: 120000 | G11: 120000 | I11: =I10+G11-H11 -> 6087800 | L11: =L10+J11-K11 -> 0
A12: 30/01/2025 | B12: 2001 | D12: PB. PRATAMA | E12: 220000 | G12: 220000 | I12: =I11+G12-H12 -> 6307800 | L12: =L11+J12-K12 -> 0
A13: 30/01/2025 | B13: 2001 | D13: PB.BALBES | E13: 120000 | G13: 120000 | I13: =I12+G13-H13 -> 6427800
A14: 30/01/2025 | B14: 2001 | D14: PB. BABAL | E14: 120000 | G14: 120000 | I14: =I13+G14-H14 -> 6547800
A15: 30/01/2025 | B15: 2001 | D15: PB. SUKRO | E15: 120000 | G15: 120000 | I15: =I14+G15-H15 -> 6667800
A16: 30/01/2025 | B16: 2001 | D16: PB. MAJU BERSAMA | E16: 120000 | G16: 120000 | I16: =I15+G16-H16 -> 6787800
A17: 30/01/2025 | B17: 2001 | D17: PB. RS BEDAH | E17: 120000 | G17: 120000 | I17: =I16+G17-H17 -> 6907800
A18: 30/01/2025 | B18: 2001 | D18: PB. SUMBER BIRU | E18: 220000 | G18: 220000 | I18: =I17+G18-H18 -> 7127800
A19: 30/01/2025 | B19: 2002 | D19: WISUDA PKK | E19: 350000 | G19: 350000 | I19: =I18+G19-H19 -> 7477800
A20: 30/01/2025 | B20: 2001 | D20: PB. KUNANG | E20: 100000 | G20: 100000 | I20: =I19+G20-H20 -> 7577800
A21: 30/01/2025 | B21: 2001 | D21: PB. AWH | E21: 120000 | G21: 120000 | I21: =I20+G21-H21 -> 7697800
A22: 30/01/2025 | B22: 5104 | D22: PULSA LISTRIK | F22: 210000 | H22: 210000 | I22: =I21+G22-H22 -> 7487800
A23: 30/01/2025 | B23: 5109 | D23: PERBAIKAN TALANG | F23: 100000 | H23: 100000 | I23: =I22+G23-H23 -> 7387800
A24: 30/01/2025 | B24: 5105 | D24: BELI LAMPU | F24: 247000 | H24: 247000 | I24: =I23+G24-H24 -> 7140800
A25: 30/01/2025 | B25: 5106 | D25: KAOS GSG | F25: 300000 | H25: 300000 | I25: =I24+G25-H25 -> 6840800
A26: 30/01/2025 | B26: 5109 | D26: BELI KRAN | F26: 15000 | H26: 15000 | I26: =I25+G26-H26 -> 6825800 | N26: KAIN PEL | O26: 45000
D27: Bulan ini | E27: =SUM(E9:E26) -> 2240000 | F27: =SUM(F9:F26) -> 872000 | G27: =SUM(G9:G26) -> 2240000 | H27: =SUM(H9:H26) -> 872000 | J27: =SUM(J10:J26) -> 0 | K27: =SUM(K10:K26) -> 0
D28: Sampai bulan ini | E28: =E8+E27 -> 7697800 | F28: =F8+F27 -> 872000 | G28: =G8+G27 -> 7697800 | H28: =H8+H27 -> 872000 | J28: =J8+J27 -> 0 | K28: =K8+K27 -> 0
D29: SALDO | E29: =E28-F28 -> 6825800 | G29: =G28-H28 -> 6825800 | J29: =J28-K28 -> 0
A31: TANGGAL | B31: CODE | C31: Penerima | D31: URAIAN | E31: UMUM | G31: KAS | J31: BANK
E32: MASUK | F32: KELUAR | G32: MASUK | H32: KELUAR | I32: SISA | J32: MASUK | K32: KELUAR | L32: SISA
A33: 1/02/2025 | D33: Saldo Bulan Januari | E33: =E29 -> 6825800 | G33: =G29 -> 6825800 | I33: =G33-H33 -> 6825800 | J33: =J29 -> 0 | L33: =J33-K33 -> 0
A34: 28-02-2025 | B34: 2001 | D34: PB. RS BEDAH | E34: 120000 | G34: 120000 | I34: =I33+G34-H34 -> 6945800 | L34: =L33+J34-K34 -> 0
A35: 28-02-2025 | B35: 2001 | D35: PB. KKMI | E35: 120000 | G35: 120000 | I35: =I34+G35-H35 -> 7065800 | L35: =L34+J35-K35 -> 0
A36: 28-02-2025 | B36: 2002 | D36: SISA PEMBAYARAN HAJATAN | E36: 1600000 | G36: 1600000 | I36: =I35+G36-H36 -> 8665800 | L36: =L35+J36-K36 -> 0
A37: 28-02-2025 | B37: 2002 | D37: PENDAPATAN TURNAMEN | E37: 100000 | G37: 100000 | I37: =I36+G37-H37 -> 8765800 | L37: =L36+J37-K37 -> 0
A38: 28-02-2025 | B38: 2001 | D38: PB. RSNU | E38: 120000 | G38: 120000 | I38: =I37+G38-H38 -> 8885800 | L38: =L37+J38-K38 -> 0
A39: 28-02-2025 | B39: 2001 | D39: PB. KUNANG | E39: 100000 | G39: 100000 | I39: =I38+G39-H39 -> 8985800 | L39: =L38+J39-K39 -> 0
A40: 28-02-2025 | B40: 2001 | D40: PB. SUMBER BIRU | E40: 120000 | G40: 120000 | I40: =I39+G40-H40 -> 9105800 | L40: =L39+J40-K40 -> 0
A41: 28-02-2025 | B41: 2001 | D41: PB. BABAL | E41: 120000 | G41: 120000 | I41: =I40+G41-H41 -> 9225800 | L41: =L40+J41-K41 -> 0
A42: 28-02-2025 | B42: 2001 | D42: PB. MAJU BERSAMA | E42: 120000 | G42: 120000 | I42: =I41+G42-H42 -> 9345800 | L42: =L41+J42-K42 -> 0
...

Sheet CTH BUMDES
A1: CATATAN HARIAN
A2: BUMDES "BAROKAH" Balongbesuk Diwek Jombang | H2: 52884579 | I2: 34391640 | J2: 34391640
A3: =gedung!A3 -> TAHUN ANGGARAN 2025 | H3: 52884579 | I3: 18582941 | J3: 18582941
H4: =H3-K7 -> 34301638 | I4: =SUM(I2:I3) -> 52974581
A5: TANGGAL | B5: CODE | C5: Penerima | E5: URAIAN | F5: UMUM | H5: KAS | K5: BANK | O5: HUTANG SHU
F6: MASUK | G6: KELUAR | H6: MASUK | I6: KELUAR | J6: SISA | K6: MASUK | L6: KELUAR | M6: SISA | O6: MASUK | P6: KELUAR | Q6: SISA
